Workbook

Sheet Employee Data
A1: Employee Id | B1: First Name | C1: Last Name | D1: Gender | E1: Age | F1: Department | G1: Job Role | H1: Location | I1: Hire Date | J1: Exit Date | K1: Employment Status | L1: Salary | M1: Performance Rating | N1: Training Hours | O1: Absence Days | P1: Overtime Hours | Q1: Promotion Status | R1: Education | S1: Manager | T1: Email | U1: Phone | V1: Employment Type | W1: Bonus | X1: Years of Service | Y1: Random Role Number
A2: ="EMP"&TEXT(ROW()-1,"000") -> EMP001 | B2: {=IF(D2="Male",INDEX(Lookup!$L$2:$L$13,RANDBETWEEN(1,12)),IF(D2="Female",INDEX(Lookup!$M$2:$M$13,RANDBETWEEN(1,12)),INDEX(Lookup!$N$2:$N$13,RANDBETWEEN(1,12))))} -> Quinn | C2: {=INDEX(Lookup!$K$2:$K$31,RANDBETWEEN(1,30))} -> Johnson | D2: {=INDEX(Lookup!$H$2:$H$4,RANDBETWEEN(1,3))} -> Other | E2: =RANDBETWEEN(21,60) -> 47 | F2: {=INDEX(Lookup!$A$2:$A$10,RANDBETWEEN(1,9))} -> Sales | G2: {=_xlfn.LET(_xlpm.Roles,_xlfn._xlws.FILTER(Lookup!$P$2:$P$28,Lookup!$O$2:$O$28=F2),INDEX(_xlpm.Roles,RANDBETWEEN(1,ROWS(_xlpm.Roles))))} -> Business Development Executive | H2: {=INDEX(Lookup!$B$2:$B$7,RANDBETWEEN(1,6))} -> Belfast | I2: =DATE(RANDBETWEEN(2018,2025),RANDBETWEEN(1,12),RANDBETWEEN(1,28)) -> 44706 | J2: =IF(K2="Resigned",I2+RANDBETWEEN(180,2000),"") -> 45767 | K2: =IF(RANDBETWEEN(1,10)<=8,"Active","Resigned") -> Resigned | L2: =_xlfn.XLOOKUP(G2,Lookup!$P$2:$P$28,Lookup!$Q$2:$Q$28)*(1+MIN(X2*3%,30%)) -> 49440 | M2: =RANDBETWEEN(1,5) -> 5 | N2: =RANDBETWEEN(0,80) -> 7 | O2: =RANDBETWEEN(0,20) -> 0 | P2: =RANDBETWEEN(0,60) -> 50 | Q2: =IF(AND(L2>=4,X2>=2,K2="Active"),"Promoted","Not Promoted") -> Not Promoted | R2: {=INDEX(Lookup!$E$2:$E$6,RANDBETWEEN(1,5))} -> Master's | S2: {=INDEX(Lookup!$J$2:$J$11,RANDBETWEEN(1,10))} -> Emma Wilson | T2: =LOWER(B2&"."&C2&"@hranalytics.com") -> quinn.johnson@hranalytics.com | U2: ="08"&RANDBETWEEN(3,9)&TEXT(RANDBETWEEN(1000000,9999999),"0000000") -> 0849510251 | V2: {=_xlfn.LET(_xlpm.r,RANDBETWEEN(1,100),_xlfn.IFS(_xlpm.r<=70,"Full-Time",_xlpm.r<=85,"Part-Time",_xlpm.r<=95,"Contract",TRUE,"Intern"))} -> Part-Time | W2: {=IF(K2<>"Active",0,_xlfn.IFS(M2=5,L2*15%,M2=4,L2*10%,M2=3,L2*5%,M2=2,L2*2%,TRUE,0))} -> 4944 | X2: =DATEDIF(I2,TODAY(),"Y") -> 4 | Y2: =RANDBETWEEN(1,3) -> 3 | AA2: {=_xlfn._xlws.FILTER(Lookup!$P$2:$P$28,Lookup!$O$2:$O$28=F2)} -> Sales Executive
A3: ="EMP"&TEXT(ROW()-1,"000") -> EMP002 | B3: {=IF(D3="Male",INDEX(Lookup!$L$2:$L$13,RANDBETWEEN(1,12)),IF(D3="Female",INDEX(Lookup!$M$2:$M$13,RANDBETWEEN(1,12)),INDEX(Lookup!$N$2:$N$13,RANDBETWEEN(1,12))))} -> Casey | C3: {=INDEX(Lookup!$K$2:$K$31,RANDBETWEEN(1,30))} -> White | D3: {=INDEX(Lookup!$H$2:$H$4,RANDBETWEEN(1,3))} -> Other | E3: =RANDBETWEEN(21,60) -> 42 | F3: {=INDEX(Lookup!$A$2:$A$10,RANDBETWEEN(1,9))} -> HR | G3: {=_xlfn.LET(_xlpm.Roles,_xlfn._xlws.FILTER(Lookup!$P$2:$P$28,Lookup!$O$2:$O$28=F3),INDEX(_xlpm.Roles,RANDBETWEEN(1,ROWS(_xlpm.Roles))))} -> HR Assistant | H3: {=INDEX(Lookup!$B$2:$B$7,RANDBETWEEN(1,6))} -> Waterford | I3: =DATE(RANDBETWEEN(2018,2025),RANDBETWEEN(1,12),RANDBETWEEN(1,28)) -> 45181 | J3: =IF(K3="Resigned",I3+RANDBETWEEN(180,2000),"") | K3: =IF(RANDBETWEEN(1,10)<=8,"Active","Resigned") -> Active | L3: =_xlfn.XLOOKUP(G3,Lookup!$P$2:$P$28,Lookup!$Q$2:$Q$28)*(1+MIN(X3*3%,30%)) -> 40120 | M3: =RANDBETWEEN(1,5) -> 4 | N3: =RANDBETWEEN(0,80) -> 44 | O3: =RANDBETWEEN(0,20) -> 13 | P3: =RANDBETWEEN(0,60) -> 54 | Q3: =IF(AND(L3>=4,X3>=2,K3="Active"),"Promoted","Not Promoted") -> Not Promoted | R3: {=INDEX(Lookup!$E$2:$E$6,RANDBETWEEN(1,5))} -> Dipolma | S3: {=INDEX(Lookup!$J$2:$J$11,RANDBETWEEN(1,10))} -> Sophia Martin | T3: =LOWER(B3&"."&C3&"@hranalytics.com") -> casey.white@hranalytics.com | U3: ="08"&RANDBETWEEN(3,9)&TEXT(RANDBETWEEN(1000000,9999999),"0000000") -> 0883399749 | V3: {=_xlfn.LET(_xlpm.r,RANDBETWEEN(1,100),_xlfn.IFS(_xlpm.r<=70,"Full-Time",_xlpm.r<=85,"Part-Time",_xlpm.r<=95,"Contract",TRUE,"Intern"))} -> Part-Time | W3: {=IF(K3<>"Active",0,_xlfn.IFS(M3=5,L3*15%,M3=4,L3*10%,M3=3,L3*5%,M3=2,L3*2%,TRUE,0))} -> 0 | X3: =DATEDIF(I3,TODAY(),"Y") -> 2 | Y3: =RANDBETWEEN(1,3) -> 3 | AA3: Account Manager
A4: ="EMP"&TEXT(ROW()-1,"000") -> EMP003 | B4: {=IF(D4="Male",INDEX(Lookup!$L$2:$L$13,RANDBETWEEN(1,12)),IF(D4="Female",INDEX(Lookup!$M$2:$M$13,RANDBETWEEN(1,12)),INDEX(Lookup!$N$2:$N$13,RANDBETWEEN(1,12))))} -> James | C4: {=INDEX(Lookup!$K$2:$K$31,RANDBETWEEN(1,30))} -> Evans | D4: {=INDEX(Lookup!$H$2:$H$4,RANDBETWEEN(1,3))} -> Male | E4: =RANDBETWEEN(21,60) -> 48 | F4: {=INDEX(Lookup!$A$2:$A$10,RANDBETWEEN(1,9))} -> Customer Support | G4: {=_xlfn.LET(_xlpm.Roles,_xlfn._xlws.FILTER(Lookup!$P$2:$P$28,Lookup!$O$2:$O$28=F4),INDEX(_xlpm.Roles,RANDBETWEEN(1,ROWS(_xlpm.Roles))))} -> Customer Success Specialist | H4: {=INDEX(Lookup!$B$2:$B$7,RANDBETWEEN(1,6))} -> Waterford | I4: =DATE(RANDBETWEEN(2018,2025),RANDBETWEEN(1,12),RANDBETWEEN(1,28)) -> 45902 | J4: =IF(K4="Resigned",I4+RANDBETWEEN(180,2000),"") | K4: =IF(RANDBETWEEN(1,10)<=8,"Active","Resigned") -> Active | L4: =_xlfn.XLOOKUP(G4,Lookup!$P$2:$P$28,Lookup!$Q$2:$Q$28)*(1+MIN(X4*3%,30%)) -> 49560 | M4: =RANDBETWEEN(1,5) -> 3 | N4: =RANDBETWEEN(0,80) -> 79 | O4: =RANDBETWEEN(0,20) -> 6 | P4: =RANDBETWEEN(0,60) -> 5 | Q4: =IF(AND(L4>=4,X4>=2,K4="Active"),"Promoted","Not Promoted") -> Promoted | R4: {=INDEX(Lookup!$E$2:$E$6,RANDBETWEEN(1,5))} -> Dipolma | S4: {=INDEX(Lookup!$J$2:$J$11,RANDBETWEEN(1,10))} -> Olivia Smith | T4: =LOWER(B4&"."&C4&"@hranalytics.com") -> james.evans@hranalytics.com | U4: ="08"&RANDBETWEEN(3,9)&TEXT(RANDBETWEEN(1000000,9999999),"0000000") -> 0898677519 | V4: {=_xlfn.LET(_xlpm.r,RANDBETWEEN(1,100),_xlfn.IFS(_xlpm.r<=70,"Full-Time",_xlpm.r<=85,"Part-Time",_xlpm.r<=95,"Contract",TRUE,"Intern"))} -> Contract | W4: {=IF(K4<>"Active",0,_xlfn.IFS(M4=5,L4*15%,M4=4,L4*10%,M4=3,L4*5%,M4=2,L4*2%,TRUE,0))} -> 991.2 | X4: =DATEDIF(I4,TODAY(),"Y") -> 0 | Y4: =RANDBETWEEN(1,3) -> 1 | AA4: Business Development Executive
A5: ="EMP"&TEXT(ROW()-1,"000") -> EMP004 | B5: {=IF(D5="Male",INDEX(Lookup!$L$2:$L$13,RANDBETWEEN(1,12)),IF(D5="Female",INDEX(Lookup!$M$2:$M$13,RANDBETWEEN(1,12)),INDEX(Lookup!$N$2:$N$13,RANDBETWEEN(1,12))))} -> Morgan | C5: {=INDEX(Lookup!$K$2:$K$31,RANDBETWEEN(1,30))} -> Wilson | D5: {=INDEX(Lookup!$H$2:$H$4,RANDBETWEEN(1,3))} -> Other | E5: =RANDBETWEEN(21,60) -> 38 | F5: {=INDEX(Lookup!$A$2:$A$10,RANDBETWEEN(1,9))} -> Customer Support | G5: {=_xlfn.LET(_xlpm.Roles,_xlfn._xlws.FILTER(Lookup!$P$2:$P$28,Lookup!$O$2:$O$28=F5),INDEX(_xlpm.Roles,RANDBETWEEN(1,ROWS(_xlpm.Roles))))} -> Customer Support Representative | H5: {=INDEX(Lookup!$B$2:$B$7,RANDBETWEEN(1,6))} -> Limerick | I5: =DATE(RANDBETWEEN(2018,2025),RANDBETWEEN(1,12),RANDBETWEEN(1,28)) -> 44066 | J5: =IF(K5="Resigned",I5+RANDBETWEEN(180,2000),"") | K5: =IF(RANDBETWEEN(1,10)<=8,"Active","Resigned") -> Active | L5: =_xlfn.XLOOKUP(G5,Lookup!$P$2:$P$28,Lookup!$Q$2:$Q$28)*(1+MIN(X5*3%,30%)) -> 38160 | M5: =RANDBETWEEN(1,5) -> 2 | N5: =RANDBETWEEN(0,80) -> 30 | O5: =RANDBETWEEN(0,20) -> 16 | P5: =RANDBETWEEN(0,60) -> 32 | Q5: =IF(AND(L5>=4,X5>=2,K5="Active"),"Promoted","Not Promoted") -> Promoted | R5: {=INDEX(Lookup!$E$2:$E$6,RANDBETWEEN(1,5))} -> High School | S5: {=INDEX(Lookup!$J$2:$J$11,RANDBETWEEN(1,10))} -> Michael Brown | T5: =LOWER(B5&"."&C5&"@hranalytics.com") -> morgan.wilson@hranalytics.com | U5: ="08"&RANDBETWEEN(3,9)&TEXT(RANDBETWEEN(1000000,9999999),"0000000") -> 0848094228 | V5: {=_xlfn.LET(_xlpm.r,RANDBETWEEN(1,100),_xlfn.IFS(_xlpm.r<=70,"Full-Time",_xlpm.r<=85,"Part-Time",_xlpm.r<=95,"Contract",TRUE,"Intern"))} -> Part-Time | W5: {=IF(K5<>"Active",0,_xlfn.IFS(M5=5,L5*15%,M5=4,L5*10%,M5=3,L5*5%,M5=2,L5*2%,TRUE,0))} -> 5724 | X5: =DATEDIF(I5,TODAY(),"Y") -> 6 | Y5: =RANDBETWEEN(1,3) -> 1
A6: ="EMP"&TEXT(ROW()-1,"000") -> EMP005 | B6: {=IF(D6="Male",INDEX(Lookup!$L$2:$L$13,RANDBETWEEN(1,12)),IF(D6="Female",INDEX(Lookup!$M$2:$M$13,RANDBETWEEN(1,12)),INDEX(Lookup!$N$2:$N$13,RANDBETWEEN(1,12))))} -> Emily | C6: {=INDEX(Lookup!$K$2:$K$31,RANDBETWEEN(1,30))} -> Campbell | D6: {=INDEX(Lookup!$H$2:$H$4,RANDBETWEEN(1,3))} -> Female | E6: =RANDBETWEEN(21,60) -> 46 | F6: {=INDEX(Lookup!$A$2:$A$10,RANDBETWEEN(1,9))} -> Legal | G6: {=_xlfn.LET(_xlpm.Roles,_xlfn._xlws.FILTER(Lookup!$P$2:$P$28,Lookup!$O$2:$O$28=F6),INDEX(_xlpm.Roles,RANDBETWEEN(1,ROWS(_xlpm.Roles))))} -> Legal Assistant | H6: {=INDEX(Lookup!$B$2:$B$7,RANDBETWEEN(1,6))} -> Galway | I6: =DATE(RANDBETWEEN(2018,2025),RANDBETWEEN(1,12),RANDBETWEEN(1,28)) -> 44220 | J6: =IF(K6="Resigned",I6+RANDBETWEEN(180,2000),"") | K6: =IF(RANDBETWEEN(1,10)<=8,"Active","Resigned") -> Active | L6: =_xlfn.XLOOKUP(G6,Lookup!$P$2:$P$28,Lookup!$Q$2:$Q$28)*(1+MIN(X6*3%,30%)) -> 49560 | M6: =RANDBETWEEN(1,5) -> 4 | N6: =RANDBETWEEN(0,80) -> 39 | O6: =RANDBETWEEN(0,20) -> 8 | P6: =RANDBETWEEN(0,60) -> 47 | Q6: =IF(AND(L6>=4,X6>=2,K6="Active"),"Promoted","Not Promoted") -> Not Promoted | R6: {=INDEX(Lookup!$E$2:$E$6,RANDBETWEEN(1,5))} -> Dipolma | S6: {=INDEX(Lookup!$J$2:$J$11,RANDBETWEEN(1,10))} -> Sophia Martin | T6: =LOWER(B6&"."&C6&"@hranalytics.com") -> emily.campbell@hranalytics.com | U6: ="08"&RANDBETWEEN(3,9)&TEXT(RANDBETWEEN(1000000,9999999),"0000000") -> 0897260195 | V6: {=_xlfn.LET(_xlpm.r,RANDBETWEEN(1,100),_xlfn.IFS(_xlpm.r<=70,"Full-Time",_xlpm.r<=85,"Part-Time",_xlpm.r<=95,"Contract",TRUE,"Intern"))} -> Full-Time | W6: {=IF(K6<>"Active",0,_xlfn.IFS(M6=5,L6*15%,M6=4,L6*10%,M6=3,L6*5%,M6=2,L6*2%,TRUE,0))} -> 0 | X6: =DATEDIF(I6,TODAY(),"Y") -> 5 | Y6: =RANDBETWEEN(1,3) -> 2
A7: ="EMP"&TEXT(ROW()-1,"000") -> EMP006 | B7: {=IF(D7="Male",INDEX(Lookup!$L$2:$L$13,RANDBETWEEN(1,12)),IF(D7="Female",INDEX(Lookup!$M$2:$M$13,RANDBETWEEN(1,12)),INDEX(Lookup!$N$2:$N$13,RANDBETWEEN(1,12))))} -> Robin | C7: {=INDEX(Lookup!$K$2:$K$31,RANDBETWEEN(1,30))} -> Green | D7: {=INDEX(Lookup!$H$2:$H$4,RANDBETWEEN(1,3))} -> Other | E7: =RANDBETWEEN(21,60) -> 51 | F7: {=INDEX(Lookup!$A$2:$A$10,RANDBETWEEN(1,9))} -> Operations | G7: {=_xlfn.LET(_xlpm.Roles,_xlfn._xlws.FILTER(Lookup!$P$2:$P$28,Lookup!$O$2:$O$28=F7),INDEX(_xlpm.Roles,RANDBETWEEN(1,ROWS(_xlpm.Roles))))} -> Operations Executive | H7: {=INDEX(Lookup!$B$2:$B$7,RANDBETWEEN(1,6))} -> Limerick | I7: =DATE(RANDBETWEEN(2018,2025),RANDBETWEEN(1,12),RANDBETWEEN(1,28)) -> 43691 | J7: =IF(K7="Resigned",I7+RANDBETWEEN(180,2000),"") | K7: =IF(RANDBETWEEN(1,10)<=8,"Active","Resigned") -> Active | L7: =_xlfn.XLOOKUP(G7,Lookup!$P$2:$P$28,Lookup!$Q$2:$Q$28)*(1+MIN(X7*3%,30%)) -> 48300 | M7: =RANDBETWEEN(1,5) -> 3 | N7: =RANDBETWEEN(0,80) -> 31 | O7: =RANDBETWEEN(0,20) -> 0 | P7: =RANDBETWEEN(0,60) -> 18 | Q7: =IF(AND(L7>=4,X7>=2,K7="Active"),"Promoted","Not Promoted") -> Promoted | R7: {=INDEX(Lookup!$E$2:$E$6,RANDBETWEEN(1,5))} -> Dipolma | S7: {=INDEX(Lookup!$J$2:$J$11,RANDBETWEEN(1,10))} -> Emma Wilson | T7: =LOWER(B7&"."&C7&"@hranalytics.com") -> robin.green@hranalytics.com | U7: ="08"&RANDBETWEEN(3,9)&TEXT(RANDBETWEEN(1000000,9999999),"0000000") -> 0898071866 | V7: {=_xlfn.LET(_xlpm.r,RANDBETWEEN(1,100),_xlfn.IFS(_xlpm.r<=70,"Full-Time",_xlpm.r<=85,"Part-Time",_xlpm.r<=95,"Contract",TRUE,"Intern"))} -> Full-Time | W7: {=IF(K7<>"Active",0,_xlfn.IFS(M7=5,L7*15%,M7=4,L7*10%,M7=3,L7*5%,M7=2,L7*2%,TRUE,0))} -> 4830 | X7: =DATEDIF(I7,TODAY(),"Y") -> 7 | Y7: =RANDBETWEEN(1,3) -> 1
A8: ="EMP"&TEXT(ROW()-1,"000") -> EMP007 | B8: {=IF(D8="Male",INDEX(Lookup!$L$2:$L$13,RANDBETWEEN(1,12)),IF(D8="Female",INDEX(Lookup!$M$2:$M$13,RANDBETWEEN(1,12)),INDEX(Lookup!$N$2:$N$13,RANDBETWEEN(1,12))))} -> John | C8: {=INDEX(Lookup!$K$2:$K$31,RANDBETWEEN(1,30))} -> Hill | D8: {=INDEX(Lookup!$H$2:$H$4,RANDBETWEEN(1,3))} -> Male | E8: =RANDBETWEEN(21,60) -> 48 | F8: {=INDEX(Lookup!$A$2:$A$10,RANDBETWEEN(1,9))} -> Operations | G8: {=_xlfn.LET(_xlpm.Roles,_xlfn._xlws.FILTER(Lookup!$P$2:$P$28,Lookup!$O$2:$O$28=F8),INDEX(_xlpm.Roles,RANDBETWEEN(1,ROWS(_xlpm.Roles))))} -> Operations Coordinator | H8: {=INDEX(Lookup!$B$2:$B$7,RANDBETWEEN(1,6))} -> Cork | I8: =DATE(RANDBETWEEN(2018,2025),RANDBETWEEN(1,12),RANDBETWEEN(1,28)) -> 44113 | J8: =IF(K8="Resigned",I8+RANDBETWEEN(180,2000),"") | K8: =IF(RANDBETWEEN(1,10)<=8,"Active","Resigned") -> Active | L8: =_xlfn.XLOOKUP(G8,Lookup!$P$2:$P$28,Lookup!$Q$2:$Q$28)*(1+MIN(X8*3%,30%)) -> 53100 | M8: =RANDBETWEEN(1,5) -> 2 | N8: =RANDBETWEEN(0,80) -> 2 | O8: =RANDBETWEEN(0,20) -> 1 | P8: =RANDBETWEEN(0,60) -> 47 | Q8: =IF(AND(L8>=4,X8>=2,K8="Active"),"Promoted","Not Promoted") -> Promoted | R8: {=INDEX(Lookup!$E$2:$E$6,RANDBETWEEN(1,5))} -> Dipolma | S8: {=INDEX(Lookup!$J$2:$J$11,RANDBETWEEN(1,10))} -> James Taylor | T8: =LOWER(B8&"."&C8&"@hranalytics.com") -> john.hill@hranalytics.com | U8: ="08"&RANDBETWEEN(3,9)&TEXT(RANDBETWEEN(1000000,9999999),"0000000") -> 0896298878 | V8: {=_xlfn.LET(_xlpm.r,RANDBETWEEN(1,100),_xlfn.IFS(_xlpm.r<=70,"Full-Time",_xlpm.r<=85,"Part-Time",_xlpm.r<=95,"Contract",TRUE,"Intern"))} -> Full-Time | W8: {=IF(K8<>"Active",0,_xlfn.IFS(M8=5,L8*15%,M8=4,L8*10%,M8=3,L8*5%,M8=2,L8*2%,TRUE,0))} -> 7965 | X8: =DATEDIF(I8,TODAY(),"Y") -> 5 | Y8: =RANDBETWEEN(1,3) -> 1
A9: ="EMP"&TEXT(ROW()-1,"000") -> EMP008 | B9: {=IF(D9="Male",INDEX(Lookup!$L$2:$L$13,RANDBETWEEN(1,12)),IF(D9="Female",INDEX(Lookup!$M$2:$M$13,RANDBETWEEN(1,12)),INDEX(Lookup!$N$2:$N$13,RANDBETWEEN(1,12))))} -> Ella | C9: {=INDEX(Lookup!$K$2:$K$31,RANDBETWEEN(1,30))} -> Johnson | D9: {=INDEX(Lookup!$H$2:$H$4,RANDBETWEEN(1,3))} -> Female | E9: =RANDBETWEEN(21,60) -> 27 | F9: {=INDEX(Lookup!$A$2:$A$10,RANDBETWEEN(1,9))} -> Marketing | G9: {=_xlfn.LET(_xlpm.Roles,_xlfn._xlws.FILTER(Lookup!$P$2:$P$28,Lookup!$O$2:$O$28=F9),INDEX(_xlpm.Roles,RANDBETWEEN(1,ROWS(_xlpm.Roles))))} -> Brand Executive | H9: {=INDEX(Lookup!$B$2:$B$7,RANDBETWEEN(1,6))} -> Cork | I9: =DATE(RANDBETWEEN(2018,2025),RANDBETWEEN(1,12),RANDBETWEEN(1,28)) -> 45915 | J9: =IF(K9="Resigned",I9+RANDBETWEEN(180,2000),"") -> 46891 | K9: =IF(RANDBETWEEN(1,10)<=8,"Active","Resigned") -> Resigned | L9: =_xlfn.XLOOKUP(G9,Lookup!$P$2:$P$28,Lookup!$Q$2:$Q$28)*(1+MIN(X9*3%,30%)) -> 51520 | M9: =RANDBETWEEN(1,5) -> 5 | N9: =RANDBETWEEN(0,80) -> 9 | O9: =RANDBETWEEN(0,20) -> 14 | P9: =RANDBETWEEN(0,60) -> 26 | Q9: =IF(AND(L9>=4,X9>=2,K9="Active"),"Promoted","Not Promoted") -> Promoted | R9: {=INDEX(Lookup!$E$2:$E$6,RANDBETWEEN(1,5))} -> Bachelor's | S9: {=INDEX(Lookup!$J$2:$J$11,RANDBETWEEN(1,10))} -> Sophia Martin | T9: =LOWER(B9&"."&C9&"@hranalytics.com") -> ella.johnson@hranalytics.com | U9: ="08"&RANDBETWEEN(3,9)&TEXT(RANDBETWEEN(1000000,9999999),"0000000") -> 0862295218 | V9: {=_xlfn.LET(_xlpm.r,RANDBETWEEN(1,100),_xlfn.IFS(_xlpm.r<=70,"Full-Time",_xlpm.r<=85,"Part-Time",_xlpm.r<=95,"Contract",TRUE,"Intern"))} -> Part-Time | W9: {=IF(K9<>"Active",0,_xlfn.IFS(M9=5,L9*15%,M9=4,L9*10%,M9=3,L9*5%,M9=2,L9*2%,TRUE,0))} -> 5152 | X9: =DATEDIF(I9,TODAY(),"Y") -> 0 | Y9: =RANDBETWEEN(1,3) -> 1
A10: ="EMP"&TEXT(ROW()-1,"000") -> EMP009 | B10: {=IF(D10="Male",INDEX(Lookup!$L$2:$L$13,RANDBETWEEN(1,12)),IF(D10="Female",INDEX(Lookup!$M$2:$M$13,RANDBETWEEN(1,12)),INDEX(Lookup!$N$2:$N$13,RANDBETWEEN(1,12))))} -> Isabella | C10: {=INDEX(Lookup!$K$2:$K$31,RANDBETWEEN(1,30))} -> Edwards | D10: {=INDEX(Lookup!$H$2:$H$4,RANDBETWEEN(1,3))} -> Female | E10: =RANDBETWEEN(21,60) -> 21 | F10: {=INDEX(Lookup!$A$2:$A$10,RANDBETWEEN(1,9))} -> Procurement | G10: {=_xlfn.LET(_xlpm.Roles,_xlfn._xlws.FILTER(Lookup!$P$2:$P$28,Lookup!$O$2:$O$28=F10),INDEX(_xlpm.Roles,RANDBETWEEN(1,ROWS(_xlpm.Roles))))} -> Purchasing Executive | H10: {=INDEX(Lookup!$B$2:$B$7,RANDBETWEEN(1,6))} -> Waterford | I10: =DATE(RANDBETWEEN(2018,2025),RANDBETWEEN(1,12),RANDBETWEEN(1,28)) -> 44666 | J10: =IF(K10="Resigned",I10+RANDBETWEEN(180,2000),"") | K10: =IF(RANDBETWEEN(1,10)<=8,"Active","Resigned") -> Active | L10: =_xlfn.XLOOKUP(G10,Lookup!$P$2:$P$28,Lookup!$Q$2:$Q$28)*(1+MIN(X10*3%,30%)) -> 44520 | M10: =RANDBETWEEN(1,5) -> 1 | N10: =RANDBETWEEN(0,80) -> 53 | O10: =RANDBETWEEN(0,20) -> 20 | P10: =RANDBETWEEN(0,60) -> 45 | Q10: =IF(AND(L10>=4,X10>=2,K10="Active"),"Promoted","Not Promoted") -> Promoted | R10: {=INDEX(Lookup!$E$2:$E$6,RANDBETWEEN(1,5))} -> Bachelor's | S10: {=INDEX(Lookup!$J$2:$J$11,RANDBETWEEN(1,10))} -> Liam Byrne | T10: =LOWER(B10&"."&C10&"@hranalytics.com") -> isabella.edwards@hranalytics.com | U10: ="08"&RANDBETWEEN(3,9)&TEXT(RANDBETWEEN(1000000,9999999),"0000000") -> 0838060506 | V10: {=_xlfn.LET(_xlpm.r,RANDBETWEEN(1,100),_xlfn.IFS(_xlpm.r<=70,"Full-Time",_xlpm.r<=85,"Part-Time",_xlpm.r<=95,"Contract",TRUE,"Intern"))} -> Part-Time | W10: {=IF(K10<>"Active",0,_xlfn.IFS(M10=5,L10*15%,M10=4,L10*10%,M10=3,L10*5%,M10=2,L10*2%,TRUE,0))} -> 4452 | X10: =DATEDIF(I10,TODAY(),"Y") -> 4 | Y10: =RANDBETWEEN(1,3) -> 2
A11: ="EMP"&TEXT(ROW()-1,"000") -> EMP010 | B11: {=IF(D11="Male",INDEX(Lookup!$L$2:$L$13,RANDBETWEEN(1,12)),IF(D11="Female",INDEX(Lookup!$M$2:$M$13,RANDBETWEEN(1,12)),INDEX(Lookup!$N$2:$N$13,RANDBETWEEN(1,12))))} -> Cameron | C11: {=INDEX(Lookup!$K$2:$K$31,RANDBETWEEN(1,30))} -> Murphy | D11: {=INDEX(Lookup!$H$2:$H$4,RANDBETWEEN(1,3))} -> Other | E11: =RANDBETWEEN(21,60) -> 31 | F11: {=INDEX(Lookup!$A$2:$A$10,RANDBETWEEN(1,9))} -> Legal | G11: {=_xlfn.LET(_xlpm.Roles,_xlfn._xlws.FILTER(Lookup!$P$2:$P$28,Lookup!$O$2:$O$28=F11),INDEX(_xlpm.Roles,RANDBETWEEN(1,ROWS(_xlpm.Roles))))} -> Legal Assistant | H11: {=INDEX(Lookup!$B$2:$B$7,RANDBETWEEN(1,6))} -> Belfast | I11: =DATE(RANDBETWEEN(2018,2025),RANDBETWEEN(1,12),RANDBETWEEN(1,28)) -> 43498 | J11: =IF(K11="Resigned",I11+RANDBETWEEN(180,2000),"") | K11: =IF(RANDBETWEEN(1,10)<=8,"Active","Resigned") -> Active | L11: =_xlfn.XLOOKUP(G11,Lookup!$P$2:$P$28,Lookup!$Q$2:$Q$28)*(1+MIN(X11*3%,30%)) -> 47040 | M11: =RANDBETWEEN(1,5) -> 2 | N11: =RANDBETWEEN(0,80) -> 34 | O11: =RANDBETWEEN(0,20) -> 16 | P11: =RANDBETWEEN(0,60) -> 53 | Q11: =IF(AND(L11>=4,X11>=2,K11="Active"),"Promoted","Not Promoted") -> Promoted | R11: {=INDEX(Lookup!$E$2:$E$6,RANDBETWEEN(1,5))} -> PhD | S11: {=INDEX(Lookup!$J$2:$J$11,RANDBETWEEN(1,10))} -> David Murphy | T11: =LOWER(B11&"."&C11&"@hranalytics.com") -> cameron.murphy@hranalytics.com | U11: ="08"&RANDBETWEEN(3,9)&TEXT(RANDBETWEEN(1000000,9999999),"0000000") -> 0896803531 | V11: {=_xlfn.LET(_xlpm.r,RANDBETWEEN(1,100),_xlfn.IFS(_xlpm.r<=70,"Full-Time",_xlpm.r<=85,"Part-Time",_xlpm.r<=95,"Contract",TRUE,"Intern"))} -> Full-Time | W11: {=IF(K11<>"Active",0,_xlfn.IFS(M11=5,L11*15%,M11=4,L11*10%,M11=3,L11*5%,M11=2,L11*2%,TRUE,0))} -> 2352 | X11: =DATEDIF(I11,TODAY(),"Y") -> 7 | Y11: =RANDBETWEEN(1,3) -> 3
A12: ="EMP"&TEXT(ROW()-1,"000") -> EMP011 | B12: {=IF(D12="Male",INDEX(Lookup!$L$2:$L$13,RANDBETWEEN(1,12)),IF(D12="Female",INDEX(Lookup!$M$2:$M$13,RANDBETWEEN(1,12)),INDEX(Lookup!$N$2:$N$13,RANDBETWEEN(1,12))))} -> William | C12: {=INDEX(Lookup!$K$2:$K$31,RANDBETWEEN(1,30))} -> Edwards | D12: {=INDEX(Lookup!$H$2:$H$4,RANDBETWEEN(1,3))} -> Male | E12: =RANDBETWEEN(21,60) -> 44 | F12: {=INDEX(Lookup!$A$2:$A$10,RANDBETWEEN(1,9))} -> IT | G12: {=_xlfn.LET(_xlpm.Roles,_xlfn._xlws.FILTER(Lookup!$P$2:$P$28,Lookup!$O$2:$O$28=F12),INDEX(_xlpm.Roles,RANDBETWEEN(1,ROWS(_xlpm.Roles))))} -> IT Support Specialist | H12: {=INDEX(Lookup!$B$2:$B$7,RANDBETWEEN(1,6))} -> Galway | I12: =DATE(RANDBETWEEN(2018,2025),RANDBETWEEN(1,12),RANDBETWEEN(1,28)) -> 45538 | J12: =IF(K12="Resigned",I12+RANDBETWEEN(180,2000),"") | K12: =IF(RANDBETWEEN(1,10)<=8,"Active","Resigned") -> Active | L12: =_xlfn.XLOOKUP(G12,Lookup!$P$2:$P$28,Lookup!$Q$2:$Q$28)*(1+MIN(X12*3%,30%)) -> 58080 | M12: =RANDBETWEEN(1,5) -> 3 | N12: =RANDBETWEEN(0,80) -> 29 | O12: =RANDBETWEEN(0,20) -> 18 | P12: =RANDBETWEEN(0,60) -> 51 | Q12: =IF(AND(L12>=4,X12>=2,K12="Active"),"Promoted","Not Promoted") -> Not Promoted | R12: {=INDEX(Lookup!$E$2:$E$6,RANDBETWEEN(1,5))} -> High School | S12: {=INDEX(Lookup!$J$2:$J$11,RANDBETWEEN(1,10))} -> Michael Brown | T12: =LOWER(B12&"."&C12&"@hranalytics.com") -> william.edwards@hranalytics.com | U12: ="08"&RANDBETWEEN(3,9)&TEXT(RANDBETWEEN(1000000,9999999),"0000000") -> 0859341457 | V12: {=_xlfn.LET(_xlpm.r,RANDBETWEEN(1,100),_xlfn.IFS(_xlpm.r<=70,"Full-Time",_xlpm.r<=85,"Part-Time",_xlpm.r<=95,"Contract",TRUE,"Intern"))} -> Full-Time | W12: {=IF(K12<>"Active",0,_xlfn.IFS(M12=5,L12*15%,M12=4,L12*10%,M12=3,L12*5%,M12=2,L12*2%,TRUE,0))} -> 0 | X12: =DATEDIF(I12,TODAY(),"Y") -> 1 | Y12: =RANDBETWEEN(1,3) -> 2
A13: ="EMP"&TEXT(ROW()-1,"000") -> EMP012 | B13: {=IF(D13="Male",INDEX(Lookup!$L$2:$L$13,RANDBETWEEN(1,12)),IF(D13="Female",INDEX(Lookup!$M$2:$M$13,RANDBETWEEN(1,12)),INDEX(Lookup!$N$2:$N$13,RANDBETWEEN(1,12))))} -> Skyler | C13: {=INDEX(Lookup!$K$2:$K$31,RANDBETWEEN(1,30))} -> Moore | D13: {=INDEX(Lookup!$H$2:$H$4,RANDBETWEEN(1,3))} -> Other | E13: =RANDBETWEEN(21,60) -> 40 | F13: {=INDEX(Lookup!$A$2:$A$10,RANDBETWEEN(1,9))} -> Finance | G13: {=_xlfn.LET(_xlpm.Roles,_xlfn._xlws.FILTER(Lookup!$P$2:$P$28,Lookup!$O$2:$O$28=F13),INDEX(_xlpm.Roles,RANDBETWEEN(1,ROWS(_xlpm.Roles))))} -> Accountant | H13: {=INDEX(Lookup!$B$2:$B$7,RANDBETWEEN(1,6))} -> Dublin | I13: =DATE(RANDBETWEEN(2018,2025),RANDBETWEEN(1,12),RANDBETWEEN(1,28)) -> 44997 | J13: =IF(K13="Resigned",I13+RANDBETWEEN(180,2000),"") | K13: =IF(RANDBETWEEN(1,10)<=8,"Active","Resigned") -> Active | L13: =_xlfn.XLOOKUP(G13,Lookup!$P$2:$P$28,Lookup!$Q$2:$Q$28)*(1+MIN(X13*3%,30%)) -> 60500 | M13: =RANDBETWEEN(1,5) -> 3 | N13: =RANDBETWEEN(0,80) -> 24 | O13: =RANDBETWEEN(0,20) -> 18 | P13: =RANDBETWEEN(0,60) -> 40 | Q13: =IF(AND(L13>=4,X13>=2,K13="Active"),"Promoted","Not Promoted") -> Promoted | R13: {=INDEX(Lookup!$E$2:$E$6,RANDBETWEEN(1,5))} -> Master's | S13: {=INDEX(Lookup!$J$2:$J$11,RANDBETWEEN(1,10))} -> James Taylor | T13: =LOWER(B13&"."&C13&"@hranalytics.com") -> skyler.moore@hranalytics.com | U13: ="08"&RANDBETWEEN(3,9)&TEXT(RANDBETWEEN(1000000,9999999),"0000000") -> 0886966414 | V13: {=_xlfn.LET(_xlpm.r,RANDBETWEEN(1,100),_xlfn.IFS(_xlpm.r<=70,"Full-Time",_xlpm.r<=85,"Part-Time",_xlpm.r<=95,"Contract",TRUE,"Intern"))} -> Full-Time | W13: {=IF(K13<>"Active",0,_xlfn.IFS(M13=5,L13*15%,M13=4,L13*10%,M13=3,L13*5%,M13=2,L13*2%,TRUE,0))} -> 1210 | X13: =DATEDIF(I13,TODAY(),"Y") -> 3 | Y13: =RANDBETWEEN(1,3) -> 1
A14: ="EMP"&TEXT(ROW()-1,"000") -> EMP013 | B14: {=IF(D14="Male",INDEX(Lookup!$L$2:$L$13,RANDBETWEEN(1,12)),IF(D14="Female",INDEX(Lookup!$M$2:$M$13,RANDBETWEEN(1,12)),INDEX(Lookup!$N$2:$N$13,RANDBETWEEN(1,12))))} -> Alex | C14: {=INDEX(Lookup!$K$2:$K$31,RANDBETWEEN(1,30))} -> Thomas | D14: {=INDEX(Lookup!$H$2:$H$4,RANDBETWEEN(1,3))} -> Other | E14: =RANDBETWEEN(21,60) -> 46 | F14: {=INDEX(Lookup!$A$2:$A$10,RANDBETWEEN(1,9))} -> Customer Support | G14: {=_xlfn.LET(_xlpm.Roles,_xlfn._xlws.FILTER(Lookup!$P$2:$P$28,Lookup!$O$2:$O$28=F14),INDEX(_xlpm.Roles,RANDBETWEEN(1,ROWS(_xlpm.Roles))))} -> Customer Success Specialist | H14: {=INDEX(Lookup!$B$2:$B$7,RANDBETWEEN(1,6))} -> Cork | I14: =DATE(RANDBETWEEN(2018,2025),RANDBETWEEN(1,12),RANDBETWEEN(1,28)) -> 44172 | J14: =IF(K14="Resigned",I14+RANDBETWEEN(180,2000),"") -> 45315 | K14: =IF(RANDBETWEEN(1,10)<=8,"Active","Resigned") -> Resigned | L14: =_xlfn.XLOOKUP(G14,Lookup!$P$2:$P$28,Lookup!$Q$2:$Q$28)*(1+MIN(X14*3%,30%)) -> 50820 | M14: =RANDBETWEEN(1,5) -> 2 | N14: =RANDBETWEEN(0,80) -> 63 | O14: =RANDBETWEEN(0,20) -> 18 | P14: =RANDBETWEEN(0,60) -> 14 | Q14: =IF(AND(L14>=4,X14>=2,K14="Active"),"Promoted","Not Promoted") -> Promoted | R14: {=INDEX(Lookup!$E$2:$E$6,RANDBETWEEN(1,5))} -> Master's | S14: {=INDEX(Lookup!$J$2:$J$11,RANDBETWEEN(1,10))} -> James Taylor | T14: =LOWER(B14&"."&C14&"@hranalytics.com") -> alex.thomas@hranalytics.com | U14: ="08"&RANDBETWEEN(3,9)&TEXT(RANDBETWEEN(1000000,9999999),"0000000") -> 0863000051 | V14: {=_xlfn.LET(_xlpm.r,RANDBETWEEN(1,100),_xlfn.IFS(_xlpm.r<=70,"Full-Time",_xlpm.r<=85,"Part-Time",_xlpm.r<=95,"Contract",TRUE,"Intern"))} -> Full-Time | W14: {=IF(K14<>"Active",0,_xlfn.IFS(M14=5,L14*15%,M14=4,L14*10%,M14=3,L14*5%,M14=2,L14*2%,TRUE,0))} -> 0 | X14: =DATEDIF(I14,TODAY(),"Y") -> 5 | Y14: =RANDBETWEEN(1,3) -> 3
A15: ="EMP"&TEXT(ROW()-1,"000") -> EMP014 | B15: {=IF(D15="Male",INDEX(Lookup!$L$2:$L$13,RANDBETWEEN(1,12)),IF(D15="Female",INDEX(Lookup!$M$2:$M$13,RANDBETWEEN(1,12)),INDEX(Lookup!$N$2:$N$13,RANDBETWEEN(1,12))))} -> Leo | C15: {=INDEX(Lookup!$K$2:$K$31,RANDBETWEEN(1,30))} -> Lewis | D15: {=INDEX(Lookup!$H$2:$H$4,RANDBETWEEN(1,3))} -> Male | E15: =RANDBETWEEN(21,60) -> 60 | F15: {=INDEX(Lookup!$A$2:$A$10,RANDBETWEEN(1,9))} -> Legal | G15: {=_xlfn.LET(_xlpm.Roles,_xlfn._xlws.FILTER(Lookup!$P$2:$P$28,Lookup!$O$2:$O$28=F15),INDEX(_xlpm.Roles,RANDBETWEEN(1,ROWS(_xlpm.Roles))))} -> Legal Executive | H15: {=INDEX(Lookup!$B$2:$B$7,RANDBETWEEN(1,6))} -> Cork | I15: =DATE(RANDBETWEEN(2018,2025),RANDBETWEEN(1,12),RANDBETWEEN(1,28)) -> 45704 | J15: =IF(K15="Resigned",I15+RANDBETWEEN(180,2000),"") | K15: =IF(RANDBETWEEN(1,10)<=8,"Active","Resigned") -> Active | L15: =_xlfn.XLOOKUP(G15,Lookup!$P$2:$P$28,Lookup!$Q$2:$Q$28)*(1+MIN(X15*3%,30%)) -> 61360 | M15: =RANDBETWEEN(1,5) -> 3 | N15: =RANDBETWEEN(0,80) -> 8 | O15: =RANDBETWEEN(0,20) -> 10 | P15: =RANDBETWEEN(0,60) -> 2 | Q15: =IF(AND(L15>=4,X15>=2,K15="Active"),"Promoted","Not Promoted") -> Not Promoted | R15: {=INDEX(Lookup!$E$2:$E$6,RANDBETWEEN(1,5))} -> High School | S15: {=INDEX(Lookup!$J$2:$J$11,RANDBETWEEN(1,10))} -> David Murphy | T15: =LOWER(B15&"."&C15&"@hranalytics.com") -> leo.lewis@hranalytics.com | U15: ="08"&RANDBETWEEN(3,9)&TEXT(RANDBETWEEN(1000000,9999999),"0000000") -> 0862002847 | V15: {=_xlfn.LET(_xlpm.r,RANDBETWEEN(1,100),_xlfn.IFS(_xlpm.r<=70,"Full-Time",_xlpm.r<=85,"Part-Time",_xlpm.r<=95,"Contract",TRUE,"Intern"))} -> Full-Time | W15: {=IF(K15<>"Active",0,_xlfn.IFS(M15=5,L15*15%,M15=4,L15*10%,M15=3,L15*5%,M15=2,L15*2%,TRUE,0))} -> 0 | X15: =DATEDIF(I15,TODAY(),"Y") -> 1 | Y15: =RANDBETWEEN(1,3) -> 2
A16: ="EMP"&TEXT(ROW()-1,"000") -> EMP015 | B16: {=IF(D16="Male",INDEX(Lookup!$L$2:$L$13,RANDBETWEEN(1,12)),IF(D16="Female",INDEX(Lookup!$M$2:$M$13,RANDBETWEEN(1,12)),INDEX(Lookup!$N$2:$N$13,RANDBETWEEN(1,12))))} -> Michael | C16: {=INDEX(Lookup!$K$2:$K$31,RANDBETWEEN(1,30))} -> Edwards | D16: {=INDEX(Lookup!$H$2:$H$4,RANDBETWEEN(1,3))} -> Male | E16: =RANDBETWEEN(21,60) -> 38 | F16: {=INDEX(Lookup!$A$2:$A$10,RANDBETWEEN(1,9))} -> HR | G16: {=_xlfn.LET(_xlpm.Roles,_xlfn._xlws.FILTER(Lookup!$P$2:$P$28,Lookup!$O$2:$O$28=F16),INDEX(_xlpm.Roles,RANDBETWEEN(1,ROWS(_xlpm.Roles))))} -> HR Executive | H16: {=INDEX(Lookup!$B$2:$B$7,RANDBETWEEN(1,6))} -> Belfast | I16: =DATE(RANDBETWEEN(2018,2025),RANDBETWEEN(1,12),RANDBETWEEN(1,28)) -> 43913 | J16: =IF(K16="Resigned",I16+RANDBETWEEN(180,2000),"") | K16: =IF(RANDBETWEEN(1,10)<=8,"Active","Resigned") -> Active | L16: =_xlfn.XLOOKUP(G16,Lookup!$P$2:$P$28,Lookup!$Q$2:$Q$28)*(1+MIN(X16*3%,30%)) -> 47040 | M16: =RANDBETWEEN(1,5) -> 4 | N16: =RANDBETWEEN(0,80) -> 71 | O16: =RANDBETWEEN(0,20) -> 15 | P16: =RANDBETWEEN(0,60) -> 15 | Q16: =IF(AND(L16>=4,X16>=2,K16="Active"),"Promoted","Not Promoted") -> Promoted | R16: {=INDEX(Lookup!$E$2:$E$6,RANDBETWEEN(1,5))} -> Dipolma | S16: {=INDEX(Lookup!$J$2:$J$11,RANDBETWEEN(1,10))} -> James Taylor | T16: =LOWER(B16&"."&C16&"@hranalytics.com") -> michael.edwards@hranalytics.com | U16: ="08"&RANDBETWEEN(3,9)&TEXT(RANDBETWEEN(1000000,9999999),"0000000") -> 0837619178 | V16: {=_xlfn.LET(_xlpm.r,RANDBETWEEN(1,100),_xlfn.IFS(_xlpm.r<=70,"Full-Time",_xlpm.r<=85,"Part-Time",_xlpm.r<=95,"Contract",TRUE,"Intern"))} -> Full-Time | W16: {=IF(K16<>"Active",0,_xlfn.IFS(M16=5,L16*15%,M16=4,L16*10%,M16=3,L16*5%,M16=2,L16*2%,TRUE,0))} -> 7056 | X16: =DATEDIF(I16,TODAY(),"Y") -> 6 | Y16: =RANDBETWEEN(1,3) -> 1
A17: ="EMP"&TEXT(ROW()-1,"000") -> EMP016 | B17: {=IF(D17="Male",INDEX(Lookup!$L$2:$L$13,RANDBETWEEN(1,12)),IF(D17="Female",INDEX(Lookup!$M$2:$M$13,RANDBETWEEN(1,12)),INDEX(Lookup!$N$2:$N$13,RANDBETWEEN(1,12))))} -> Emma | C17: {=INDEX(Lookup!$K$2:$K$31,RANDBETWEEN(1,30))} -> Green | D17: {=INDEX(Lookup!$H$2:$H$4,RANDBETWEEN(1,3))} -> Female | E17: =RANDBETWEEN(21,60) -> 55 | F17: {=INDEX(Lookup!$A$2:$A$10,RANDBETWEEN(1,9))} -> IT | G17: {=_xlfn.LET(_xlpm.Roles,_xlfn._xlws.FILTER(Lookup!$P$2:$P$28,Lookup!$O$2:$O$28=F17),INDEX(_xlpm.Roles,RANDBETWEEN(1,ROWS(_xlpm.Roles))))} -> Data Analyst | H17: {=INDEX(Lookup!$B$2:$B$7,RANDBETWEEN(1,6))} -> Waterford | I17: =DATE(RANDBETWEEN(2018,2025),RANDBETWEEN(1,12),RANDBETWEEN(1,28)) -> 43224 | J17: =IF(K17="Resigned",I17+RANDBETWEEN(180,2000),"") | K17: =IF(RANDBETWEEN(1,10)<=8,"Active","Resigned") -> Active | L17: =_xlfn.XLOOKUP(G17,Lookup!$P$2:$P$28,Lookup!$Q$2:$Q$28)*(1+MIN(X17*3%,30%)) -> 56650 | M17: =RANDBETWEEN(1,5) -> 4 | N17: =RANDBETWEEN(0,80) -> 20 | O17: =RANDBETWEEN(0,20) -> 19 | P17: =RANDBETWEEN(0,60) -> 21 | Q17: =IF(AND(L17>=4,X17>=2,K17="Active"),"Promoted","Not Promoted") -> Not Promoted | R17: {=INDEX(Lookup!$E$2:$E$6,RANDBETWEEN(1,5))} -> Dipolma | S17: {=INDEX(Lookup!$J$2:$J$11,RANDBETWEEN(1,10))} -> David Murphy | T17: =LOWER(B17&"."&C17&"@hranalytics.com") -> emma.green@hranalytics.com | U17: ="08"&RANDBETWEEN(3,9)&TEXT(RANDBETWEEN(1000000,9999999),"0000000") -> 0866328318 | V17: {=_xlfn.LET(_xlpm.r,RANDBETWEEN(1,100),_xlfn.IFS(_xlpm.r<=70,"Full-Time",_xlpm.r<=85,"Part-Time",_xlpm.r<=95,"Contract",TRUE,"Intern"))} -> Full-Time | W17: {=IF(K17<>"Active",0,_xlfn.IFS(M17=5,L17*15%,M17=4,L17*10%,M17=3,L17*5%,M17=2,L17*2%,TRUE,0))} -> 0 | X17: =DATEDIF(I17,TODAY(),"Y") -> 8 | Y17: =RANDBETWEEN(1,3) -> 3
A18: ="EMP"&TEXT(ROW()-1,"000") -> EMP017 | B18: {=IF(D18="Male",INDEX(Lookup!$L$2:$L$13,RANDBETWEEN(1,12)),IF(D18="Female",INDEX(Lookup!$M$2:$M$13,RANDBETWEEN(1,12)),INDEX(Lookup!$N$2:$N$13,RANDBETWEEN(1,12))))} -> Mia | C18: {=INDEX(Lookup!$K$2:$K$31,RANDBETWEEN(1,30))} -> Moore | D18: {=INDEX(Lookup!$H$2:$H$4,RANDBETWEEN(1,3))} -> Female | E18: =RANDBETWEEN(21,60) -> 32 | F18: {=INDEX(Lookup!$A$2:$A$10,RANDBETWEEN(1,9))} -> Procurement | G18: {=_xlfn.LET(_xlpm.Roles,_xlfn._xlws.FILTER(Lookup!$P$2:$P$28,Lookup!$O$2:$O$28=F18),INDEX(_xlpm.Roles,RANDBETWEEN(1,ROWS(_xlpm.Roles))))} -> Procurement Officer | H18: {=INDEX(Lookup!$B$2:$B$7,RANDBETWEEN(1,6))} -> Cork | I18: =DATE(RANDBETWEEN(2018,2025),RANDBETWEEN(1,12),RANDBETWEEN(1,28)) -> 44350 | J18: =IF(K2="Resigned",I2+RANDBETWEEN(180,MIN(2000,TODAY()-I2)),"") -> 45273 | K18: =IF(RANDBETWEEN(1,10)<=8,"Active","Resigned") -> Active | L18: =_xlfn.XLOOKUP(G18,Lookup!$P$2:$P$28,Lookup!$Q$2:$Q$28)*(1+MIN(X18*3%,30%)) -> 51750 | M18: =RANDBETWEEN(1,5) -> 3 | N18: =RANDBETWEEN(0,80) -> 64 | O18: =RANDBETWEEN(0,20) -> 18 | P18: =RANDBETWEEN(0,60) -> 31 | Q18: =IF(AND(L18>=4,X18>=2,K18="Active"),"Promoted","Not Promoted") -> Not Promoted | R18: {=INDEX(Lookup!$E$2:$E$6,RANDBETWEEN(1,5))} -> High School | S18: {=INDEX(Lookup!$J$2:$J$11,RANDBETWEEN(1,10))} -> Emma Wilson | T18: =LOWER(B18&"."&C18&"@hranalytics.com") -> mia.moore@hranalytics.com | U18: ="08"&RANDBETWEEN(3,9)&TEXT(RANDBETWEEN(1000000,9999999),"0000000") -> 0886951665 | V18: {=_xlfn.LET(_xlpm.r,RANDBETWEEN(1,100),_xlfn.IFS(_xlpm.r<=70,"Full-Time",_xlpm.r<=85,"Part-Time",_xlpm.r<=95,"Contract",TRUE,"Intern"))} -> Full-Time | W18: {=IF(K18<>"Active",0,_xlfn.IFS(M18=5,L18*15%,M18=4,L18*10%,M18=3,L18*5%,M18=2,L18*2%,TRUE,0))} -> 0 | X18: =DATEDIF(I18,TODAY(),"Y") -> 5 | Y18: =RANDBETWEEN(1,3) -> 2
A19: ="EMP"&TEXT(ROW()-1,"000") -> EMP018 | B19: {=IF(D19="Male",INDEX(Lookup!$L$2:$L$13,RANDBETWEEN(1,12)),IF(D19="Female",INDEX(Lookup!$M$2:$M$13,RANDBETWEEN(1,12)),INDEX(Lookup!$N$2:$N$13,RANDBETWEEN(1,12))))} -> Olivia | C19: {=INDEX(Lookup!$K$2:$K$31,RANDBETWEEN(1,30))} -> King | D19: {=INDEX(Lookup!$H$2:$H$4,RANDBETWEEN(1,3))} -> Female | E19: =RANDBETWEEN(21,60) -> 46 | F19: {=INDEX(Lookup!$A$2:$A$10,RANDBETWEEN(1,9))} -> Finance | G19: {=_xlfn.LET(_xlpm.Roles,_xlfn._xlws.FILTER(Lookup!$P$2:$P$28,Lookup!$O$2:$O$28=F19),INDEX(_xlpm.Roles,RANDBETWEEN(1,ROWS(_xlpm.Roles))))} -> Financial Analyst | H19: {=INDEX(Lookup!$B$2:$B$7,RANDBETWEEN(1,6))} -> Limerick | I19: =DATE(RANDBETWEEN(2018,2025),RANDBETWEEN(1,12),RANDBETWEEN(1,28)) -> 43696 | J19: =IF(K19="Resigned",I19+RANDBETWEEN(180,2000),"") -> 44039 | K19: =IF(RANDBETWEEN(1,10)<=8,"Active","Resigned") -> Resigned | L19: =_xlfn.XLOOKUP(G19,Lookup!$P$2:$P$28,Lookup!$Q$2:$Q$28)*(1+MIN(X19*3%,30%)) -> 64960 | M19: =RANDBETWEEN(1,5) -> 1 | N19: =RANDBETWEEN(0,80) -> 74 | O19: =RANDBETWEEN(0,20) -> 11 | P19: =RANDBETWEEN(0,60) -> 58 | Q19: =IF(AND(L19>=4,X19>=2,K19="Active"),"Promoted","Not Promoted") -> Not Promoted | R19: {=INDEX(Lookup!$E$2:$E$6,RANDBETWEEN(1,5))} -> Master's | S19: {=INDEX(Lookup!$J$2:$J$11,RANDBETWEEN(1,10))} -> Olivia Smith | T19: =LOWER(B19&"."&C19&"@hranalytics.com") -> olivia.king@hranalytics.com | U19: ="08"&RANDBETWEEN(3,9)&TEXT(RANDBETWEEN(1000000,9999999),"0000000") -> 0889353836 | V19: {=_xlfn.LET(_xlpm.r,RANDBETWEEN(1,100),_xlfn.IFS(_xlpm.r<=70,"Full-Time",_xlpm.r<=85,"Part-Time",_xlpm.r<=95,"Contract",TRUE,"Intern"))} -> Full-Time | W19: {=IF(K19<>"Active",0,_xlfn.IFS(M19=5,L19*15%,M19=4,L19*10%,M19=3,L19*5%,M19=2,L19*2%,TRUE,0))} -> 0 | X19: =DATEDIF(I19,TODAY(),"Y") -> 7 | Y19: =RANDBETWEEN(1,3) -> 3
A20: ="EMP"&TEXT(ROW()-1,"000") -> EMP019 | B20: {=IF(D2="Male",INDEX(Lookup!$L$2:$L$13,RANDBETWEEN(1,12)),IF(D2="Female",INDEX(Lookup!$M$2:$M$13,RANDBETWEEN(1,12)),INDEX(Lookup!$N$2:$N$13,RANDBETWEEN(1,12))))} -> Quinn | C20: {=INDEX(Lookup!$K$2:$K$31,RANDBETWEEN(1,30))} -> Campbell | D20: {=INDEX(Lookup!$H$2:$H$4,RANDBETWEEN(1,3))} -> Other | E20: =RANDBETWEEN(21,60) -> 30 | F20: {=INDEX(Lookup!$A$2:$A$10,RANDBETWEEN(1,9))} -> IT | G20: {=_xlfn.LET(_xlpm.Roles,_xlfn._xlws.FILTER(Lookup!$P$2:$P$28,Lookup!$O$2:$O$28=F20),INDEX(_xlpm.Roles,RANDBETWEEN(1,ROWS(_xlpm.Roles))))} -> IT Support Specialist | H20: {=INDEX(Lookup!$B$2:$B$7,RANDBETWEEN(1,6))} -> Waterford | I20: =DATE(RANDBETWEEN(2018,2025),RANDBETWEEN(1,12),RANDBETWEEN(1,28)) -> 43606 | J20: =IF(K2="Resigned",I2+RANDBETWEEN(180,MIN(2000,TODAY()-I2)),"") -> 45472 | K20: =IF(RANDBETWEEN(1,10)<=8,"Active","Resigned") -> Active | L20: =_xlfn.XLOOKUP(G20,Lookup!$P$2:$P$28,Lookup!$Q$2:$Q$28)*(1+MIN(X20*3%,30%)) -> 52320 | M20: =RANDBETWEEN(1,5) -> 4 | N20: =RANDBETWEEN(0,80) -> 16 | O20: =RANDBETWEEN(0,20) -> 12 | P20: =RANDBETWEEN(0,60) -> 8 | Q20: =IF(AND(L20>=4,X20>=2,K20="Active"),"Promoted","Not Promoted") -> Promoted | R20: {=INDEX(Lookup!$E$2:$E$6,RANDBETWEEN(1,5))} -> Bachelor's | S20: {=INDEX(Lookup!$J$2:$J$11,RANDBETWEEN(1,10))} -> Sarah Johnson | T20: =LOWER(B20&"."&C20&"@hranalytics.com") -> quinn.campbell@hranalytics.com | U20: ="08"&RANDBETWEEN(3,9)&TEXT(RANDBETWEEN(1000000,9999999),"0000000") -> 0865081300 | V20: {=_xlfn.LET(_xlpm.r,RANDBETWEEN(1,100),_xlfn.IFS(_xlpm.r<=70,"Full-Time",_xlpm.r<=85,"Part-Time",_xlpm.r<=95,"Contract",TRUE,"Intern"))} -> Part-Time | W20: {=IF(K20<>"Active",0,_xlfn.IFS(M20=5,L20*15%,M20=4,L20*10%,M20=3,L20*5%,M20=2,L20*2%,TRUE,0))} -> 7848 | X20: =DATEDIF(I20,TODAY(),"Y") -> 7 | Y20: =RANDBETWEEN(1,3) -> 2
A21: ="EMP"&TEXT(ROW()-1,"000") -> EMP020 | B21: {=IF(D21="Male",INDEX(Lookup!$L$2:$L$13,RANDBETWEEN(1,12)),IF(D21="Female",INDEX(Lookup!$M$2:$M$13,RANDBETWEEN(1,12)),INDEX(Lookup!$N$2:$N$13,RANDBETWEEN(1,12))))} -> Emma | C21: {=INDEX(Lookup!$K$2:$K$31,RANDBETWEEN(1,30))} -> Kelly | D21: {=INDEX(Lookup!$H$2:$H$4,RANDBETWEEN(1,3))} -> Female | E21: =RANDBETWEEN(21,60) -> 59 | F21: {=INDEX(Lookup!$A$2:$A$10,RANDBETWEEN(1,9))} -> Marketing | G21: {=_xlfn.LET(_xlpm.Roles,_xlfn._xlws.FILTER(Lookup!$P$2:$P$28,Lookup!$O$2:$O$28=F21),INDEX(_xlpm.Roles,RANDBETWEEN(1,ROWS(_xlpm.Roles))))} -> Brand Executive | H21: {=INDEX(Lookup!$B$2:$B$7,RANDBETWEEN(1,6))} -> Cork | I21: =DATE(RANDBETWEEN(2018,2025),RANDBETWEEN(1,12),RANDBETWEEN(1,28)) -> 44728 | J21: =IF(K2="Resigned",I2+RANDBETWEEN(180,MIN(2000,TODAY()-I2)),"") -> 45267 | K21: =IF(RANDBETWEEN(1,10)<=8,"Active","Resigned") -> Active | L21: =_xlfn.XLOOKUP(G21,Lookup!$P$2:$P$28,Lookup!$Q$2:$Q$28)*(1+MIN(X21*3%,30%)) -> 47380 | M21: =RANDBETWEEN(1,5) -> 2 | N21: =RANDBETWEEN(0,80) -> 15 | O21: =RANDBETWEEN(0,20) -> 9 | P21: =RANDBETWEEN(0,60) -> 11 | Q21: =IF(AND(L21>=4,X21>=2,K21="Active"),"Promoted","Not Promoted") -> Not Promoted | R21: {=INDEX(Lookup!$E$2:$E$6,RANDBETWEEN(1,5))} -> PhD | S21: {=INDEX(Lookup!$J$2:$J$11,RANDBETWEEN(1,10))} -> Olivia Smith | T21: =LOWER(B21&"."&C21&"@hranalytics.com") -> emma.kelly@hranalytics.com | U21: ="08"&RANDBETWEEN(3,9)&TEXT(RANDBETWEEN(1000000,9999999),"0000000") -> 0854044750 | V21: {=_xlfn.LET(_xlpm.r,RANDBETWEEN(1,100),_xlfn.IFS(_xlpm.r<=70,"Full-Time",_xlpm.r<=85,"Part-Time",_xlpm.r<=95,"Contract",TRUE,"Intern"))} -> Full-Time | W21: {=IF(K21<>"Active",0,_xlfn.IFS(M21=5,L21*15%,M21=4,L21*10%,M21=3,L21*5%,M21=2,L21*2%,TRUE,0))} -> 0 | X21: =DATEDIF(I21,TODAY(),"Y") -> 4 | Y21: =RANDBETWEEN(1,3) -> 2
A22: ="EMP"&TEXT(ROW()-1,"000") -> EMP021 | B22: {=IF(D22="Male",INDEX(Lookup!$L$2:$L$13,RANDBETWEEN(1,12)),IF(D22="Female",INDEX(Lookup!$M$2:$M$13,RANDBETWEEN(1,12)),INDEX(Lookup!$N$2:$N$13,RANDBETWEEN(1,12))))} -> Skyler | C22: {=INDEX(Lookup!$K$2:$K$31,RANDBETWEEN(1,30))} -> Turner | D22: {=INDEX(Lookup!$H$2:$H$4,RANDBETWEEN(1,3))} -> Other | E22: =RANDBETWEEN(21,60) -> 31 | F22: {=INDEX(Lookup!$A$2:$A$10,RANDBETWEEN(1,9))} -> Marketing | G22: {=_xlfn.LET(_xlpm.Roles,_xlfn._xlws.FILTER(Lookup!$P$2:$P$28,Lookup!$O$2:$O$28=F22),INDEX(_xlpm.Roles,RANDBETWEEN(1,ROWS(_xlpm.Roles))))} -> Marketing Executive | H22: {=INDEX(Lookup!$B$2:$B$7,RANDBETWEEN(1,6))} -> Limerick | I22: =DATE(RANDBETWEEN(2018,2025),RANDBETWEEN(1,12),RANDBETWEEN(1,28)) -> 43761 | J22: =IF(K22="Resigned",I22+RANDBETWEEN(180,2000),"") | K22: =IF(RANDBETWEEN(1,10)<=8,"Active","Resigned") -> Active | L22: =_xlfn.XLOOKUP(G22,Lookup!$P$2:$P$28,Lookup!$Q$2:$Q$28)*(1+MIN(X22*3%,30%)) -> 45780 | M22: =RANDBETWEEN(1,5) -> 1 | N22: =RANDBETWEEN(0,80) -> 21 | O22: =RANDBETWEEN(0,20) -> 14 | P22: =RANDBETWEEN(0,60) -> 57 | Q22: =IF(AND(L22>=4,X22>=2,K22="Active"),"Promoted","Not Promoted") -> Not Promoted | R22: {=INDEX(Lookup!$E$2:$E$6,RANDBETWEEN(1,5))} -> PhD | S22: {=INDEX(Lookup!$J$2:$J$11,RANDBETWEEN(1,10))} -> Michael Brown | T22: =LOWER(B22&"."&C22&"@hranalytics.com") -> skyler.turner@hranalytics.com | U22: ="08"&RANDBETWEEN(3,9)&TEXT(RANDBETWEEN(1000000,9999999),"0000000") -> 0887834344 | V22: {=_xlfn.LET(_xlpm.r,RANDBETWEEN(1,100),_xlfn.IFS(_xlpm.r<=70,"Full-Time",_xlpm.r<=85,"Part-Time",_xlpm.r<=95,"Contract",TRUE,"Intern"))} -> Full-Time | W22: {=IF(K22<>"Active",0,_xlfn.IFS(M22=5,L22*15%,M22=4,L22*10%,M22=3,L22*5%,M22=2,L22*2%,TRUE,0))} -> 0 | X22: =DATEDIF(I22,TODAY(),"Y") -> 6 | Y22: =RANDBETWEEN(1,3) -> 2
A23: ="EMP"&TEXT(ROW()-1,"000") -> EMP022 | B23: {=IF(D23="Male",INDEX(Lookup!$L$2:$L$13,RANDBETWEEN(1,12)),IF(D23="Female",INDEX(Lookup!$M$2:$M$13,RANDBETWEEN(1,12)),INDEX(Lookup!$N$2:$N$13,RANDBETWEEN(1,12))))} -> Alex | C23: {=INDEX(Lookup!$K$2:$K$31,RANDBETWEEN(1,30))} -> Hill | D23: {=INDEX(Lookup!$H$2:$H$4,RANDBETWEEN(1,3))} -> Other | E23: =RANDBETWEEN(21,60) -> 54 | F23: {=INDEX(Lookup!$A$2:$A$10,RANDBETWEEN(1,9))} -> Procurement | G23: {=_xlfn.LET(_xlpm.Roles,_xlfn._xlws.FILTER(Lookup!$P$2:$P$28,Lookup!$O$2:$O$28=F23),INDEX(_xlpm.Roles,RANDBETWEEN(1,ROWS(_xlpm.Roles))))} -> Procurement Analyst | H23: {=INDEX(Lookup!$B$2:$B$7,RANDBETWEEN(1,6))} -> Cork | I23: =DATE(RANDBETWEEN(2018,2025),RANDBETWEEN(1,12),RANDBETWEEN(1,28)) -> 44908 | J23: =IF(K23="Resigned",I23+RANDBETWEEN(180,2000),"") | K23: =IF(RANDBETWEEN(1,10)<=8,"Active","Resigned") -> Active | L23: =_xlfn.XLOOKUP(G23,Lookup!$P$2:$P$28,Lookup!$Q$2:$Q$28)*(1+MIN(X23*3%,30%)) -> 60500 | M23: =RANDBETWEEN(1,5) -> 2 | N23: =RANDBETWEEN(0,80) -> 69 | O23: =RANDBETWEEN(0,20) -> 6 | P23: =RANDBETWEEN(0,60) -> 43 | Q23: =IF(AND(L23>=4,X23>=2,K23="Active"),"Promoted","Not Promoted") -> Promoted | R23: {=INDEX(Lookup!$E$2:$E$6,RANDBETWEEN(1,5))} -> Master's | S23: {=INDEX(Lookup!$J$2:$J$11,RANDBETWEEN(1,10))} -> Liam Byrne | T23: =LOWER(B23&"."&C23&"@hranalytics.com") -> alex.hill@hranalytics.com | U23: ="08"&RANDBETWEEN(3,9)&TEXT(RANDBETWEEN(1000000,9999999),"0000000") -> 0854109332 | V23: {=_xlfn.LET(_xlpm.r,RANDBETWEEN(1,100),_xlfn.IFS(_xlpm.r<=70,"Full-Time",_xlpm.r<=85,"Part-Time",_xlpm.r<=95,"Contract",TRUE,"Intern"))} -> Part-Time | W23: {=IF(K23<>"Active",0,_xlfn.IFS(M23=5,L23*15%,M23=4,L23*10%,M23=3,L23*5%,M23=2,L23*2%,TRUE,0))} -> 6050 | X23: =DATEDIF(I23,TODAY(),"Y") -> 3 | Y23: =RANDBETWEEN(1,3) -> 2
A24: ="EMP"&TEXT(ROW()-1,"000") -> EMP023 | B24: {=IF(D24="Male",INDEX(Lookup!$L$2:$L$13,RANDBETWEEN(1,12)),IF(D24="Female",INDEX(Lookup!$M$2:$M$13,RANDBETWEEN(1,12)),INDEX(Lookup!$N$2:$N$13,RANDBETWEEN(1,12))))} -> Morgan | C24: {=INDEX(Lookup!$K$2:$K$31,RANDBETWEEN(1,30))} -> Scott | D24: {=INDEX(Lookup!$H$2:$H$4,RANDBETWEEN(1,3))} -> Other | E24: =RANDBETWEEN(21,60) -> 28 | F24: {=INDEX(Lookup!$A$2:$A$10,RANDBETWEEN(1,9))} -> Legal | G24: {=_xlfn.LET(_xlpm.Roles,_xlfn._xlws.FILTER(Lookup!$P$2:$P$28,Lookup!$O$2:$O$28=F24),INDEX(_xlpm.Roles,RANDBETWEEN(1,ROWS(_xlpm.Roles))))} -> Legal Executive | H24: {=INDEX(Lookup!$B$2:$B$7,RANDBETWEEN(1,6))} -> Galway | I24: =DATE(RANDBETWEEN(2018,2025),RANDBETWEEN(1,12),RANDBETWEEN(1,28)) -> 45803 | J24: =IF(K24="Resigned",I24+RANDBETWEEN(180,2000),"") | K24: =IF(RANDBETWEEN(1,10)<=8,"Active","Resigned") -> Active | L24: =_xlfn.XLOOKUP(G24,Lookup!$P$2:$P$28,Lookup!$Q$2:$Q$28)*(1+MIN(X24*3%,30%)) -> 53560 | M24: =RANDBETWEEN(1,5) -> 1 | N24: =RANDBETWEEN(0,80) -> 61 | O24: =RANDBETWEEN(0,20) -> 14 | P24: =RANDBETWEEN(0,60) -> 20 | Q24: =IF(AND(L24>=4,X24>=2,K24="Active"),"Promoted","Not Promoted") -> Not Promoted | R24: {=INDEX(Lookup!$E$2:$E$6,RANDBETWEEN(1,5))} -> PhD | S24: {=INDEX(Lookup!$J$2:$J$11,RANDBETWEEN(1,10))} -> Olivia Smith | T24: =LOWER(B24&"."&C24&"@hranalytics.com") -> morgan.scott@hranalytics.com | U24: ="08"&RANDBETWEEN(3,9)&TEXT(RANDBETWEEN(1000000,9999999),"0000000") -> 0859362823 | V24: {=_xlfn.LET(_xlpm.r,RANDBETWEEN(1,100),_xlfn.IFS(_xlpm.r<=70,"Full-Time",_xlpm.r<=85,"Part-Time",_xlpm.r<=95,"Contract",TRUE,"Intern"))} -> Contract | W24: {=IF(K24<>"Active",0,_xlfn.IFS(M24=5,L24*15%,M24=4,L24*10%,M24=3,L24*5%,M24=2,L24*2%,TRUE,0))} -> 2678 | X24: =DATEDIF(I24,TODAY(),"Y") -> 1 | Y24: =RANDBETWEEN(1,3) -> 3
A25: ="EMP"&TEXT(ROW()-1,"000") -> EMP024 | B25: {=IF(D25="Male",INDEX(Lookup!$L$2:$L$13,RANDBETWEEN(1,12)),IF(D25="Female",INDEX(Lookup!$M$2:$M$13,RANDBETWEEN(1,12)),INDEX(Lookup!$N$2:$N$13,RANDBETWEEN(1,12))))} -> Oliver | C25: {=INDEX(Lookup!$K$2:$K$31,RANDBETWEEN(1,30))} -> Scott | D25: {=INDEX(Lookup!$H$2:$H$4,RANDBETWEEN(1,3))} -> Male | E25: =RANDBETWEEN(21,60) -> 48 | F25: {=INDEX(Lookup!$A$2:$A$10,RANDBETWEEN(1,9))} -> Legal | G25: {=_xlfn.LET(_xlpm.Roles,_xlfn._xlws.FILTER(Lookup!$P$2:$P$28,Lookup!$O$2:$O$28=F25),INDEX(_xlpm.Roles,RANDBETWEEN(1,ROWS(_xlpm.Roles))))} -> Legal Executive | H25: {=INDEX(Lookup!$B$2:$B$7,RANDBETWEEN(1,6))} -> Dublin | I25: =DATE(RANDBETWEEN(2018,2025),RANDBETWEEN(1,12),RANDBETWEEN(1,28)) -> 44695 | J25: =IF(K25="Resigned",I25+RANDBETWEEN(180,2000),"") | K25: =IF(RANDBETWEEN(1,10)<=8,"Active","Resigned") -> Active | L25: =_xlfn.XLOOKUP(G25,Lookup!$P$2:$P$28,Lookup!$Q$2:$Q$28)*(1+MIN(X25*3%,30%)) -> 61360 | M25: =RANDBETWEEN(1,5) -> 3 | N25: =RANDBETWEEN(0,80) -> 22 | O25: =RANDBETWEEN(0,20) -> 16 | P25: =RANDBETWEEN(0,60) -> 55 | Q25: =IF(AND(L25>=4,X25>=2,K25="Active"),"Promoted","Not Promoted") -> Not Promoted | R25: {=INDEX(Lookup!$E$2:$E$6,RANDBETWEEN(1,5))} -> PhD | S25: {=INDEX(Lookup!$J$2:$J$11,RANDBETWEEN(1,10))} -> Sarah Johnson | T25: =LOWER(B25&"."&C25&"@hranalytics.com") -> oliver.scott@hranalytics.com | U25: ="08"&RANDBETWEEN(3,9)&TEXT(RANDBETWEEN(1000000,9999999),"0000000") -> 0832430130 | V25: {=_xlfn.LET(_xlpm.r,RANDBETWEEN(1,100),_xlfn.IFS(_xlpm.r<=70,"Full-Time",_xlpm.r<=85,"Part-Time",_xlpm.r<=95,"Contract",TRUE,"Intern"))} -> Part-Time | W25: {=IF(K25<>"Active",0,_xlfn.IFS(M25=5,L25*15%,M25=4,L25*10%,M25=3,L25*5%,M25=2,L25*2%,TRUE,0))} -> 0 | X25: =DATEDIF(I25,TODAY(),"Y") -> 4 | Y25: =RANDBETWEEN(1,3) -> 3
A26: ="EMP"&TEXT(ROW()-1,"000") -> EMP025 | B26: {=IF(D26="Male",INDEX(Lookup!$L$2:$L$13,RANDBETWEEN(1,12)),IF(D26="Female",INDEX(Lookup!$M$2:$M$13,RANDBETWEEN(1,12)),INDEX(Lookup!$N$2:$N$13,RANDBETWEEN(1,12))))} -> Oliver | C26: {=INDEX(Lookup!$K$2:$K$31,RANDBETWEEN(1,30))} -> King | D26: {=INDEX(Lookup!$H$2:$H$4,RANDBETWEEN(1,3))} -> Male | E26: =RANDBETWEEN(21,60) -> 39 | F26: {=INDEX(Lookup!$A$2:$A$10,RANDBETWEEN(1,9))} -> Customer Support | G26: {=_xlfn.LET(_xlpm.Roles,_xlfn._xlws.FILTER(Lookup!$P$2:$P$28,Lookup!$O$2:$O$28=F26),INDEX(_xlpm.Roles,RANDBETWEEN(1,ROWS(_xlpm.Roles))))} -> Customer Success Specialist | H26: {=INDEX(Lookup!$B$2:$B$7,RANDBETWEEN(1,6))} -> Cork | I26: =DATE(RANDBETWEEN(2018,2025),RANDBETWEEN(1,12),RANDBETWEEN(1,28)) -> 43638 | J26: =IF(K26="Resigned",I26+RANDBETWEEN(180,2000),"") -> 45566 | K26: =IF(RANDBETWEEN(1,10)<=8,"Active","Resigned") -> Resigned | L26: =_xlfn.XLOOKUP(G26,Lookup!$P$2:$P$28,Lookup!$Q$2:$Q$28)*(1+MIN(X26*3%,30%)) -> 42000 | M26: =RANDBETWEEN(1,5) -> 4 | N26: =RANDBETWEEN(0,80) -> 65 | O26: =RANDBETWEEN(0,20) -> 11 | P26: =RANDBETWEEN(0,60) -> 37 | Q26: =IF(AND(L26>=4,X26>=2,K26="Active"),"Promoted","Not Promoted") -> Not Promoted | R26: {=INDEX(Lookup!$E$2:$E$6,RANDBETWEEN(1,5))} -> Master's | S26: {=INDEX(Lookup!$J$2:$J$11,RANDBETWEEN(1,10))} -> Liam Byrne | T26: =LOWER(B26&"."&C26&"@hranalytics.com") -> oliver.king@hranalytics.com | U26: ="08"&RANDBETWEEN(3,9)&TEXT(RANDBETWEEN(1000000,9999999),"0000000") -> 0851396735 | V26: {=_xlfn.LET(_xlpm.r,RANDBETWEEN(1,100),_xlfn.IFS(_xlpm.r<=70,"Full-Time",_xlpm.r<=85,"Part-Time",_xlpm.r<=95,"Contract",TRUE,"Intern"))} -> Part-Time | W26: {=IF(K26<>"Active",0,_xlfn.IFS(M26=5,L26*15%,M26=4,L26*10%,M26=3,L26*5%,M26=2,L26*2%,TRUE,0))} -> 4200 | X26: =DATEDIF(I26,TODAY(),"Y") -> 7 | Y26: =RANDBETWEEN(1,3) -> 2
A27: ="EMP"&TEXT(ROW()-1,"000") -> EMP026 | B27: {=IF(D27="Male",INDEX(Lookup!$L$2:$L$13,RANDBETWEEN(1,12)),IF(D27="Female",INDEX(Lookup!$M$2:$M$13,RANDBETWEEN(1,12)),INDEX(Lookup!$N$2:$N$13,RANDBETWEEN(1,12))))} -> Leo | C27: {=INDEX(Lookup!$K$2:$K$31,RANDBETWEEN(1,30))} -> Green | D27: {=INDEX(Lookup!$H$2:$H$4,RANDBETWEEN(1,3))} -> Male | E27: =RANDBETWEEN(21,60) -> 45 | F27: {=INDEX(Lookup!$A$2:$A$10,RANDBETWEEN(1,9))} -> Operations | G27: {=_xlfn.LET(_xlpm.Roles,_xlfn._xlws.FILTER(Lookup!$P$2:$P$28,Lookup!$O$2:$O$28=F27),INDEX(_xlpm.Roles,RANDBETWEEN(1,ROWS(_xlpm.Roles))))} -> Operations Manager | H27: {=INDEX(Lookup!$B$2:$B$7,RANDBETWEEN(1,6))} -> Waterford | I27: =DATE(RANDBETWEEN(2018,2025),RANDBETWEEN(1,12),RANDBETWEEN(1,28)) -> 43163 | J27: =IF(K27="Resigned",I27+RANDBETWEEN(180,2000),"") | K27: =IF(RANDBETWEEN(1,10)<=8,"Active","Resigned") -> Active | L27: =_xlfn.XLOOKUP(G27,Lookup!$P$2:$P$28,Lookup!$Q$2:$Q$28)*(1+MIN(X27*3%,30%)) -> 62000 | M27: =RANDBETWEEN(1,5) -> 2 | N27: =RANDBETWEEN(0,80) -> 54 | O27: =RANDBETWEEN(0,20) -> 1 | P27: =RANDBETWEEN(0,60) -> 49 | Q27: =IF(AND(L27>=4,X27>=2,K27="Active"),"Promoted","Not Promoted") -> Not Promoted | R27: {=INDEX(Lookup!$E$2:$E$6,RANDBETWEEN(1,5))} -> Dipolma | S27: {=INDEX(Lookup!$J$2:$J$11,RANDBETWEEN(1,10))} -> Liam Byrne | T27: =LOWER(B27&"."&C27&"@hranalytics.com") -> leo.green@hranalytics.com | U27: ="08"&RANDBETWEEN(3,9)&TEXT(RANDBETWEEN(1000000,9999999),"0000000") -> 0888970958 | V27: {=_xlfn.LET(_xlpm.r,RANDBETWEEN(1,100),_xlfn.IFS(_xlpm.r<=70,"Full-Time",_xlpm.r<=85,"Part-Time",_xlpm.r<=95,"Contract",TRUE,"Intern"))} -> Part-Time | W27: {=IF(K27<>"Active",0,_xlfn.IFS(M27=5,L27*15%,M27=4,L27*10%,M27=3,L27*5%,M27=2,L27*2%,TRUE,0))} -> 1240 | X27: =DATEDIF(I27,TODAY(),"Y") -> 8 | Y27: =RANDBETWEEN(1,3) -> 2
A28: ="EMP"&TEXT(ROW()-1,"000") -> EMP027 | B28: {=IF(D28="Male",INDEX(Lookup!$L$2:$L$13,RANDBETWEEN(1,12)),IF(D28="Female",INDEX(Lookup!$M$2:$M$13,RANDBETWEEN(1,12)),INDEX(Lookup!$N$2:$N$13,RANDBETWEEN(1,12))))} -> Emily | C28: {=INDEX(Lookup!$K$2:$K$31,RANDBETWEEN(1,30))} -> Kelly | D28: {=INDEX(Lookup!$H$2:$H$4,RANDBETWEEN(1,3))} -> Female | E28: =RANDBETWEEN(21,60) -> 30 | F28: {=INDEX(Lookup!$A$2:$A$10,RANDBETWEEN(1,9))} -> HR | G28: {=_xlfn.LET(_xlpm.Roles,_xlfn._xlws.FILTER(Lookup!$P$2:$P$28,Lookup!$O$2:$O$28=F28),INDEX(_xlpm.Roles,RANDBETWEEN(1,ROWS(_xlpm.Roles))))} -> HR Executive | H28: {=INDEX(Lookup!$B$2:$B$7,RANDBETWEEN(1,6))} -> Waterford | I28: =DATE(RANDBETWEEN(2018,2025),RANDBETWEEN(1,12),RANDBETWEEN(1,28)) -> 44153 | J28: =IF(K28="Resigned",I28+RANDBETWEEN(180,2000),"") | K28: =IF(RANDBETWEEN(1,10)<=8,"Active","Resigned") -> Active | L28: =_xlfn.XLOOKUP(G28,Lookup!$P$2:$P$28,Lookup!$Q$2:$Q$28)*(1+MIN(X28*3%,30%)) -> 43260 | M28: =RANDBETWEEN(1,5) -> 3 | N28: =RANDBETWEEN(0,80) -> 25 | O28: =RANDBETWEEN(0,20) -> 3 | P28: =RANDBETWEEN(0,60) -> 26 | Q28: =IF(AND(L28>=4,X28>=2,K28="Active"),"Promoted","Not Promoted") -> Not Promoted | R28: {=INDEX(Lookup!$E$2:$E$6,RANDBETWEEN(1,5))} -> PhD | S28: {=INDEX(Lookup!$J$2:$J$11,RANDBETWEEN(1,10))} -> David Murphy | T28: =LOWER(B28&"."&C28&"@hranalytics.com") -> emily.kelly@hranalytics.com | U28: ="08"&RANDBETWEEN(3,9)&TEXT(RANDBETWEEN(1000000,9999999),"0000000") -> 0839753750 | V28: {=_xlfn.LET(_xlpm.r,RANDBETWEEN(1,100),_xlfn.IFS(_xlpm.r<=70,"Full-Time",_xlpm.r<=85,"Part-Time",_xlpm.r<=95,"Contract",TRUE,"Intern"))} -> Full-Time | W28: {=IF(K28<>"Active",0,_xlfn.IFS(M28=5,L28*15%,M28=4,L28*10%,M28=3,L28*5%,M28=2,L28*2%,TRUE,0))} -> 865.2 | X28: =DATEDIF(I28,TODAY(),"Y") -> 5 | Y28: =RANDBETWEEN(1,3) -> 1
A29: ="EMP"&TEXT(ROW()-1,"000") -> EMP028 | B29: {=IF(D29="Male",INDEX(Lookup!$L$2:$L$13,RANDBETWEEN(1,12)),IF(D29="Female",INDEX(Lookup!$M$2:$M$13,RANDBETWEEN(1,12)),INDEX(Lookup!$N$2:$N$13,RANDBETWEEN(1,12))))} -> Jamie | C29: {=INDEX(Lookup!$K$2:$K$31,RANDBETWEEN(1,30))} -> Walker | D29: {=INDEX(Lookup!$H$2:$H$4,RANDBETWEEN(1,3))} -> Other | E29: =RANDBETWEEN(21,60) -> 50 | F29: {=INDEX(Lookup!$A$2:$A$10,RANDBETWEEN(1,9))} -> IT | G29: {=_xlfn.LET(_xlpm.Roles,_xlfn._xlws.FILTER(Lookup!$P$2:$P$28,Lookup!$O$2:$O$28=F29),INDEX(_xlpm.Roles,RANDBETWEEN(1,ROWS(_xlpm.Roles))))} -> IT Support Specialist | H29: {=INDEX(Lookup!$B$2:$B$7,RANDBETWEEN(1,6))} -> Limerick | I29: =DATE(RANDBETWEEN(2018,2025),RANDBETWEEN(1,12),RANDBETWEEN(1,28)) -> 45253 | J29: =IF(K29="Resigned",I29+RANDBETWEEN(180,2000),"") -> 46586 | K29: =IF(RANDBETWEEN(1,10)<=8,"Active","Resigned") -> Resigned | L29: =_xlfn.XLOOKUP(G29,Lookup!$P$2:$P$28,Lookup!$Q$2:$Q$28)*(1+MIN(X29*3%,30%)) -> 55200 | M29: =RANDBETWEEN(1,5) -> 1 | N29: =RANDBETWEEN(0,80) -> 76 | O29: =RANDBETWEEN(0,20) -> 7 | P29: =RANDBETWEEN(0,60) -> 57 | Q29: =IF(AND(L29>=4,X29>=2,K29="Active"),"Promoted","Not Promoted") -> Not Promoted | R29: {=INDEX(Lookup!$E$2:$E$6,RANDBETWEEN(1,5))} -> Bachelor's | S29: {=INDEX(Lookup!$J$2:$J$11,RANDBETWEEN(1,10))} -> Sophia Martin | T29: =LOWER(B29&"."&C29&"@hranalytics.com") -> jamie.walker@hranalytics.com | U29: ="08"&RANDBETWEEN(3,9)&TEXT(RANDBETWEEN(1000000,9999999),"0000000") -> 0869833418 | V29: {=_xlfn.LET(_xlpm.r,RANDBETWEEN(1,100),_xlfn.IFS(_xlpm.r<=70,"Full-Time",_xlpm.r<=85,"Part-Time",_xlpm.r<=95,"Contract",TRUE,"Intern"))} -> Part-Time | W29: {=IF(K29<>"Active",0,_xlfn.IFS(M29=5,L29*15%,M29=4,L29*10%,M29=3,L29*5%,M29=2,L29*2%,TRUE,0))} -> 0 | X29: =DATEDIF(I29,TODAY(),"Y") -> 2 | Y29: =RANDBETWEEN(1,3) -> 1
A30: ="EMP"&TEXT(ROW()-1,"000") -> EMP029 | B30: {=IF(D30="Male",INDEX(Lookup!$L$2:$L$13,RANDBETWEEN(1,12)),IF(D30="Female",INDEX(Lookup!$M$2:$M$13,RANDBETWEEN(1,12)),INDEX(Lookup!$N$2:$N$13,RANDBETWEEN(1,12))))} -> James | C30: {=INDEX(Lookup!$K$2:$K$31,RANDBETWEEN(1,30))} -> King | D30: {=INDEX(Lookup!$H$2:$H$4,RANDBETWEEN(1,3))} -> Male | E30: =RANDBETWEEN(21,60) -> 38 | F30: {=INDEX(Lookup!$A$2:$A$10,RANDBETWEEN(1,9))} -> HR | G30: {=_xlfn.LET(_xlpm.Roles,_xlfn._xlws.FILTER(Lookup!$P$2:$P$28,Lookup!$O$2:$O$28=F30),INDEX(_xlpm.Roles,RANDBETWEEN(1,ROWS(_xlpm.Roles))))} -> HR Assistant | H30: {=INDEX(Lookup!$B$2:$B$7,RANDBETWEEN(1,6))} -> Galway | I30: =DATE(RANDBETWEEN(2018,2025),RANDBETWEEN(1,12),RANDBETWEEN(1,28)) -> 44443 | J30: =IF(K30="Resigned",I30+RANDBETWEEN(180,2000),"") | K30: =IF(RANDBETWEEN(1,10)<=8,"Active","Resigned") -> Active | L30: =_xlfn.XLOOKUP(G30,Lookup!$P$2:$P$28,Lookup!$Q$2:$Q$28)*(1+MIN(X30*3%,30%)) -> 37060 | M30: =RANDBETWEEN(1,5) -> 4 | N30: =RANDBETWEEN(0,80) -> 16 | O30: =RANDBETWEEN(0,20) -> 3 | P30: =RANDBETWEEN(0,60) -> 51 | Q30: =IF(AND(L30>=4,X30>=2,K30="Active"),"Promoted","Not Promoted") -> Promoted | R30: {=INDEX(Lookup!$E$2:$E$6,RANDBETWEEN(1,5))} -> Master's | S30: {=INDEX(Lookup!$J$2:$J$11,RANDBETWEEN(1,10))} -> Grace O'Connor | T30: =LOWER(B30&"."&C30&"@hranalytics.com") -> james.king@hranalytics.com | U30: ="08"&RANDBETWEEN(3,9)&TEXT(RANDBETWEEN(1000000,9999999),"0000000") -> 0837922666 | V30: {=_xlfn.LET(_xlpm.r,RANDBETWEEN(1,100),_xlfn.IFS(_xlpm.r<=70,"Full-Time",_xlpm.r<=85,"Part-Time",_xlpm.r<=95,"Contract",TRUE,"Intern"))} -> Full-Time | W30: {=IF(K30<>"Active",0,_xlfn.IFS(M30=5,L30*15%,M30=4,L30*10%,M30=3,L30*5%,M30=2,L30*2%,TRUE,0))} -> 741.2 | X30: =DATEDIF(I30,TODAY(),"Y") -> 4 | Y30: =RANDBETWEEN(1,3) -> 3
A31: ="EMP"&TEXT(ROW()-1,"000") -> EMP030 | B31: {=IF(D31="Male",INDEX(Lookup!$L$2:$L$13,RANDBETWEEN(1,12)),IF(D31="Female",INDEX(Lookup!$M$2:$M$13,RANDBETWEEN(1,12)),INDEX(Lookup!$N$2:$N$13,RANDBETWEEN(1,12))))} -> Daniel | C31: {=INDEX(Lookup!$K$2:$K$31,RANDBETWEEN(1,30))} -> Scott | D31: {=INDEX(Lookup!$H$2:$H$4,RANDBETWEEN(1,3))} -> Male | E31: =RANDBETWEEN(21,60) -> 52 | F31: {=INDEX(Lookup!$A$2:$A$10,RANDBETWEEN(1,9))} -> Finance | G31: {=_xlfn.LET(_xlpm.Roles,_xlfn._xlws.FILTER(Lookup!$P$2:$P$28,Lookup!$O$2:$O$28=F31),INDEX(_xlpm.Roles,RANDBETWEEN(1,ROWS(_xlpm.Roles))))} -> Financial Analyst | H31: {=INDEX(Lookup!$B$2:$B$7,RANDBETWEEN(1,6))} -> Limerick | I31: =DATE(RANDBETWEEN(2018,2025),RANDBETWEEN(1,12),RANDBETWEEN(1,28)) -> 43231 | J31: =IF(K31="Resigned",I31+RANDBETWEEN(180,2000),"") | K31: =IF(RANDBETWEEN(1,10)<=8,"Active","Resigned") -> Active | L31: =_xlfn.XLOOKUP(G31,Lookup!$P$2:$P$28,Lookup!$Q$2:$Q$28)*(1+MIN(X31*3%,30%)) -> 66700 | M31: =RANDBETWEEN(1,5) -> 3 | N31: =RANDBETWEEN(0,80) -> 0 | O31: =RANDBETWEEN(0,20) -> 20 | P31: =RANDBETWEEN(0,60) -> 10 | Q31: =IF(AND(L31>=4,X31>=2,K31="Active"),"Promoted","Not Promoted") -> Promoted | R31: {=INDEX(Lookup!$E$2:$E$6,RANDBETWEEN(1,5))} -> PhD | S31: {=INDEX(Lookup!$J$2:$J$11,RANDBETWEEN(1,10))} -> Emma Wilson | T31: =LOWER(B31&"."&C31&"@hranalytics.com") -> daniel.scott@hranalytics.com | U31: ="08"&RANDBETWEEN(3,9)&TEXT(RANDBETWEEN(1000000,9999999),"0000000") -> 0835466860 | V31: {=_xlfn.LET(_xlpm.r,RANDBETWEEN(1,100),_xlfn.IFS(_xlpm.r<=70,"Full-Time",_xlpm.r<=85,"Part-Time",_xlpm.r<=95,"Contract",TRUE,"Intern"))} -> Full-Time | W31: {=IF(K31<>"Active",0,_xlfn.IFS(M31=5,L31*15%,M31=4,L31*10%,M31=3,L31*5%,M31=2,L31*2%,TRUE,0))} -> 3335 | X31: =DATEDIF(I31,TODAY(),"Y") -> 8 | Y31: =RANDBETWEEN(1,3) -> 2
A32: ="EMP"&TEXT(ROW()-1,"000") -> EMP031 | B32: {=IF(D32="Male",INDEX(Lookup!$L$2:$L$13,RANDBETWEEN(1,12)),IF(D32="Female",INDEX(Lookup!$M$2:$M$13,RANDBETWEEN(1,12)),INDEX(Lookup!$N$2:$N$13,RANDBETWEEN(1,12))))} -> Emma | C32: {=INDEX(Lookup!$K$2:$K$31,RANDBETWEEN(1,30))} -> Adams | D32: {=INDEX(Lookup!$H$2:$H$4,RANDBETWEEN(1,3))} -> Female | E32: =RANDBETWEEN(21,60) -> 47 | F32: {=INDEX(Lookup!$A$2:$A$10,RANDBETWEEN(1,9))} -> Customer Support | G32: {=_xlfn.LET(_xlpm.Roles,_xlfn._xlws.FILTER(Lookup!$P$2:$P$28,Lookup!$O$2:$O$28=F32),INDEX(_xlpm.Roles,RANDBETWEEN(1,ROWS(_xlpm.Roles))))} -> Customer Support Representative | H32: {=INDEX(Lookup!$B$2:$B$7,RANDBETWEEN(1,6))} -> Cork | I32: =DATE(RANDBETWEEN(2018,2025),RANDBETWEEN(1,12),RANDBETWEEN(1,28)) -> 44233 | J32: =IF(K32="Resigned",I32+RANDBETWEEN(180,2000),"") | K32: =IF(RANDBETWEEN(1,10)<=8,"Active","Resigned") -> Active | L32: =_xlfn.XLOOKUP(G32,Lookup!$P$2:$P$28,Lookup!$Q$2:$Q$28)*(1+MIN(X32*3%,30%)) -> 38160 | M32: =RANDBETWEEN(1,5) -> 2 | N32: =RANDBETWEEN(0,80) -> 62 | O32: =RANDBETWEEN(0,20) -> 14 | P32: =RANDBETWEEN(0,60) -> 15 | Q32: =IF(AND(L32>=4,X32>=2,K32="Active"),"Promoted","Not Promoted") -> Not Promoted | R32: {=INDEX(Lookup!$E$2:$E$6,RANDBETWEEN(1,5))} -> High School | S32: {=INDEX(Lookup!$J$2:$J$11,RANDBETWEEN(1,10))} -> Michael Brown | T32: =LOWER(B32&"."&C32&"@hranalytics.com") -> emma.adams@hranalytics.com | U32: ="08"&RANDBETWEEN(3,9)&TEXT(RANDBETWEEN(1000000,9999999),"0000000") -> 0834561194 | V32: {=_xlfn.LET(_xlpm.r,RANDBETWEEN(1,100),_xlfn.IFS(_xlpm.r<=70,"Full-Time",_xlpm.r<=85,"Part-Time",_xlpm.r<=95,"Contract",TRUE,"Intern"))} -> Part-Time | W32: {=IF(K32<>"Active",0,_xlfn.IFS(M32=5,L32*15%,M32=4,L32*10%,M32=3,L32*5%,M32=2,L32*2%,TRUE,0))} -> 0 | X32: =DATEDIF(I32,TODAY(),"Y") -> 5 | Y32: =RANDBETWEEN(1,3) -> 3
A33: ="EMP"&TEXT(ROW()-1,"000") -> EMP032 | B33: {=IF(D33="Male",INDEX(Lookup!$L$2:$L$13,RANDBETWEEN(1,12)),IF(D33="Female",INDEX(Lookup!$M$2:$M$13,RANDBETWEEN(1,12)),INDEX(Lookup!$N$2:$N$13,RANDBETWEEN(1,12))))} -> Olivia | C33: {=INDEX(Lookup!$K$2:$K$31,RANDBETWEEN(1,30))} -> Cooper | D33: {=INDEX(Lookup!$H$2:$H$4,RANDBETWEEN(1,3))} -> Female | E33: =RANDBETWEEN(21,60) -> 25 | F33: {=INDEX(Lookup!$A$2:$A$10,RANDBETWEEN(1,9))} -> Legal | G33: {=_xlfn.LET(_xlpm.Roles,_xlfn._xlws.FILTER(Lookup!$P$2:$P$28,Lookup!$O$2:$O$28=F33),INDEX(_xlpm.Roles,RANDBETWEEN(1,ROWS(_xlpm.Roles))))} -> Legal Assistant | H33: {=INDEX(Lookup!$B$2:$B$7,RANDBETWEEN(1,6))} -> Dublin | I33: =DATE(RANDBETWEEN(2018,2025),RANDBETWEEN(1,12),RANDBETWEEN(1,28)) -> 44113 | J33: =IF(K33="Resigned",I33+RANDBETWEEN(180,2000),"") | K33: =IF(RANDBETWEEN(1,10)<=8,"Active","Resigned") -> Active | L33: =_xlfn.XLOOKUP(G33,Lookup!$P$2:$P$28,Lookup!$Q$2:$Q$28)*(1+MIN(X33*3%,30%)) -> 50820 | M33: =RANDBETWEEN(1,5) -> 5 | N33: =RANDBETWEEN(0,80) -> 70 | O33: =RANDBETWEEN(0,20) -> 6 | P33: =RANDBETWEEN(0,60) -> 57 | Q33: =IF(AND(L33>=4,X33>=2,K33="Active"),"Promoted","Not Promoted") -> Not Promoted | R33: {=INDEX(Lookup!$E$2:$E$6,RANDBETWEEN(1,5))} -> Master's | S33: {=INDEX(Lookup!$J$2:$J$11,RANDBETWEEN(1,10))} -> Olivia Smith | T33: =LOWER(B33&"."&C33&"@hranalytics.com") -> olivia.cooper@hranalytics.com | U33: ="08"&RANDBETWEEN(3,9)&TEXT(RANDBETWEEN(1000000,9999999),"0000000") -> 0849723767 | V33: {=_xlfn.LET(_xlpm.r,RANDBETWEEN(1,100),_xlfn.IFS(_xlpm.r<=70,"Full-Time",_xlpm.r<=85,"Part-Time",_xlpm.r<=95,"Contract",TRUE,"Intern"))} -> Full-Time | W33: {=IF(K33<>"Active",0,_xlfn.IFS(M33=5,L33*15%,M33=4,L33*10%,M33=3,L33*5%,M33=2,L33*2%,TRUE,0))} -> 0 | X33: =DATEDIF(I33,TODAY(),"Y") -> 5 | Y33: =RANDBETWEEN(1,3) -> 3
... A501: ="EMP"&TEXT(ROW()-1,"000") -> EMP500 | B501: {=IF(D501="Male",INDEX(Lookup!$L$2:$L$13,RANDBETWEEN(1,12)),IF(D501="Female",INDEX(Lookup!$M$2:$M$13,RANDBETWEEN(1,12)),INDEX(Lookup!$N$2:$N$13,RANDBETWEEN(1,12))))} -> Ella | C501: {=INDEX(Lookup!$K$2:$K$31,RANDBETWEEN(1,30))} -> Hall | D501: {=INDEX(Lookup!$H$2:$H$4,RANDBETWEEN(1,3))} -> Female | E501: =RANDBETWEEN(21,60) -> 32 | F501: {=INDEX(Lookup!$A$2:$A$10,RANDBETWEEN(1,9))} -> Marketing | G501: {=_xlfn.LET(_xlpm.Roles,_xlfn._xlws.FILTER(Lookup!$P$2:$P$28,Lookup!$O$2:$O$28=F501),INDEX(_xlpm.Roles,RANDBETWEEN(1,ROWS(_xlpm.Roles))))} -> Brand Executive | H501: {=INDEX(Lookup!$B$2:$B$7,RANDBETWEEN(1,6))} -> Cork | I501: =DATE(RANDBETWEEN(2018,2025),RANDBETWEEN(1,12),RANDBETWEEN(1,28)) -> 44275 | J501: =IF(K501="Resigned",I501+RANDBETWEEN(180,2000),"") | K501: =IF(RANDBETWEEN(1,10)<=8,"Active","Resigned") -> Active | L501: =_xlfn.XLOOKUP(G501,Lookup!$P$2:$P$28,Lookup!$Q$2:$Q$28)*(1+MIN(X501*3%,30%)) -> 51520 | M501: =RANDBETWEEN(1,5) -> 3 | N501: =RANDBETWEEN(0,80) -> 79 | O501: =RANDBETWEEN(0,20) -> 12 | P501: =RANDBETWEEN(0,60) -> 25 | Q501: =IF(AND(L501>=4,X501>=2,K501="Active"),"Promoted","Not Promoted") -> Not Promoted | R501: {=INDEX(Lookup!$E$2:$E$6,RANDBETWEEN(1,5))} -> PhD | S501: {=INDEX(Lookup!$J$2:$J$11,RANDBETWEEN(1,10))} -> Daniel Kelly | T501: =LOWER(B501&"."&C501&"@hranalytics.com") -> ella.hall@hranalytics.com | U501: ="08"&RANDBETWEEN(3,9)&TEXT(RANDBETWEEN(1000000,9999999),"0000000") -> 0897821456 | V501: {=_xlfn.LET(_xlpm.r,RANDBETWEEN(1,100),_xlfn.IFS(_xlpm.r<=70,"Full-Time",_xlpm.r<=85,"Part-Time",_xlpm.r<=95,"Contract",TRUE,"Intern"))} -> Full-Time | W501: {=IF(K501<>"Active",0,_xlfn.IFS(M501=5,L501*15%,M501=4,L501*10%,M501=3,L501*5%,M501=2,L501*2%,TRUE,0))} -> 0 | X501: =DATEDIF(I501,TODAY(),"Y") -> 5 | Y501: =RANDBETWEEN(1,3) -> 3

Sheet Lookup
